[2022-11-12 21:02:08 +0800] [15496] [INFO] Starting gunicorn 20.1.0
[2022-11-12 21:02:08 +0800] [15496] [INFO] Listening at: http://0.0.0.0:5000 (15496)
[2022-11-12 21:02:08 +0800] [15496] [INFO] Using worker: sync
[2022-11-12 21:02:08 +0800] [15497] [INFO] Booting worker with pid: 15497
[2022-11-12 21:02:08 +0800] [15498] [INFO] Booting worker with pid: 15498
[2022-11-12 21:02:08 +0800] [15499] [INFO] Booting worker with pid: 15499
[2022-11-12 21:02:08 +0800] [15500] [INFO] Booting worker with pid: 15500
/home/ubuntu/virtualenv/vulndemo/lib/python3.10/site-packages/urllib3/connectionpool.py:1045: InsecureRequestWarning: Unverified HTTPS request is being made to host 'api.weixin.qq.com'. Adding certificate verification is strongly advised. See: https://urllib3.readthedocs.io/en/1.26.x/advanced-usage.html#ssl-warnings
  warnings.warn(
/home/ubuntu/virtualenv/vulndemo/lib/python3.10/site-packages/urllib3/connectionpool.py:1045: InsecureRequestWarning: Unverified HTTPS request is being made to host 'api.weixin.qq.com'. Adding certificate verification is strongly advised. See: https://urllib3.readthedocs.io/en/1.26.x/advanced-usage.html#ssl-warnings
  warnings.warn(
/home/ubuntu/virtualenv/vulndemo/lib/python3.10/site-packages/urllib3/connectionpool.py:1045: InsecureRequestWarning: Unverified HTTPS request is being made to host 'api.weixin.qq.com'. Adding certificate verification is strongly advised. See: https://urllib3.readthedocs.io/en/1.26.x/advanced-usage.html#ssl-warnings
  warnings.warn(
/home/ubuntu/virtualenv/vulndemo/lib/python3.10/site-packages/urllib3/connectionpool.py:1045: InsecureRequestWarning: Unverified HTTPS request is being made to host 'api.weixin.qq.com'. Adding certificate verification is strongly advised. See: https://urllib3.readthedocs.io/en/1.26.x/advanced-usage.html#ssl-warnings
  warnings.warn(
/home/ubuntu/virtualenv/vulndemo/lib/python3.10/site-packages/urllib3/connectionpool.py:1045: InsecureRequestWarning: Unverified HTTPS request is being made to host 'api.weixin.qq.com'. Adding certificate verification is strongly advised. See: https://urllib3.readthedocs.io/en/1.26.x/advanced-usage.html#ssl-warnings
  warnings.warn(
/home/ubuntu/virtualenv/vulndemo/lib/python3.10/site-packages/urllib3/connectionpool.py:1045: InsecureRequestWarning: Unverified HTTPS request is being made to host 'api.weixin.qq.com'. Adding certificate verification is strongly advised. See: https://urllib3.readthedocs.io/en/1.26.x/advanced-usage.html#ssl-warnings
  warnings.warn(
/home/ubuntu/virtualenv/vulndemo/lib/python3.10/site-packages/urllib3/connectionpool.py:1045: InsecureRequestWarning: Unverified HTTPS request is being made to host 'api.weixin.qq.com'. Adding certificate verification is strongly advised. See: https://urllib3.readthedocs.io/en/1.26.x/advanced-usage.html#ssl-warnings
  warnings.warn(
/home/ubuntu/virtualenv/vulndemo/lib/python3.10/site-packages/urllib3/connectionpool.py:1045: InsecureRequestWarning: Unverified HTTPS request is being made to host 'api.weixin.qq.com'. Adding certificate verification is strongly advised. See: https://urllib3.readthedocs.io/en/1.26.x/advanced-usage.html#ssl-warnings
  warnings.warn(
/home/ubuntu/virtualenv/vulndemo/lib/python3.10/site-packages/urllib3/connectionpool.py:1045: InsecureRequestWarning: Unverified HTTPS request is being made to host 'api.weixin.qq.com'. Adding certificate verification is strongly advised. See: https://urllib3.readthedocs.io/en/1.26.x/advanced-usage.html#ssl-warnings
  warnings.warn(
/home/ubuntu/virtualenv/vulndemo/lib/python3.10/site-packages/urllib3/connectionpool.py:1045: InsecureRequestWarning: Unverified HTTPS request is being made to host 'api.weixin.qq.com'. Adding certificate verification is strongly advised. See: https://urllib3.readthedocs.io/en/1.26.x/advanced-usage.html#ssl-warnings
  warnings.warn(
/home/ubuntu/virtualenv/vulndemo/lib/python3.10/site-packages/urllib3/connectionpool.py:1045: InsecureRequestWarning: Unverified HTTPS request is being made to host 'api.weixin.qq.com'. Adding certificate verification is strongly advised. See: https://urllib3.readthedocs.io/en/1.26.x/advanced-usage.html#ssl-warnings
  warnings.warn(
/home/ubuntu/virtualenv/vulndemo/lib/python3.10/site-packages/urllib3/connectionpool.py:1045: InsecureRequestWarning: Unverified HTTPS request is being made to host 'api.weixin.qq.com'. Adding certificate verification is strongly advised. See: https://urllib3.readthedocs.io/en/1.26.x/advanced-usage.html#ssl-warnings
  warnings.warn(
/home/ubuntu/virtualenv/vulndemo/lib/python3.10/site-packages/urllib3/connectionpool.py:1045: InsecureRequestWarning: Unverified HTTPS request is being made to host 'api.weixin.qq.com'. Adding certificate verification is strongly advised. See: https://urllib3.readthedocs.io/en/1.26.x/advanced-usage.html#ssl-warnings
  warnings.warn(
/home/ubuntu/virtualenv/vulndemo/lib/python3.10/site-packages/urllib3/connectionpool.py:1045: InsecureRequestWarning: Unverified HTTPS request is being made to host 'api.weixin.qq.com'. Adding certificate verification is strongly advised. See: https://urllib3.readthedocs.io/en/1.26.x/advanced-usage.html#ssl-warnings
  warnings.warn(
/home/ubuntu/virtualenv/vulndemo/lib/python3.10/site-packages/urllib3/connectionpool.py:1045: InsecureRequestWarning: Unverified HTTPS request is being made to host 'api.weixin.qq.com'. Adding certificate verification is strongly advised. See: https://urllib3.readthedocs.io/en/1.26.x/advanced-usage.html#ssl-warnings
  warnings.warn(
/home/ubuntu/virtualenv/vulndemo/lib/python3.10/site-packages/urllib3/connectionpool.py:1045: InsecureRequestWarning: Unverified HTTPS request is being made to host 'api.weixin.qq.com'. Adding certificate verification is strongly advised. See: https://urllib3.readthedocs.io/en/1.26.x/advanced-usage.html#ssl-warnings
  warnings.warn(
/home/ubuntu/virtualenv/vulndemo/lib/python3.10/site-packages/urllib3/connectionpool.py:1045: InsecureRequestWarning: Unverified HTTPS request is being made to host 'api.weixin.qq.com'. Adding certificate verification is strongly advised. See: https://urllib3.readthedocs.io/en/1.26.x/advanced-usage.html#ssl-warnings
  warnings.warn(
/home/ubuntu/virtualenv/vulndemo/lib/python3.10/site-packages/urllib3/connectionpool.py:1045: InsecureRequestWarning: Unverified HTTPS request is being made to host 'api.weixin.qq.com'. Adding certificate verification is strongly advised. See: https://urllib3.readthedocs.io/en/1.26.x/advanced-usage.html#ssl-warnings
  warnings.warn(
/home/ubuntu/virtualenv/vulndemo/lib/python3.10/site-packages/urllib3/connectionpool.py:1045: InsecureRequestWarning: Unverified HTTPS request is being made to host 'api.weixin.qq.com'. Adding certificate verification is strongly advised. See: https://urllib3.readthedocs.io/en/1.26.x/advanced-usage.html#ssl-warnings
  warnings.warn(
/home/ubuntu/virtualenv/vulndemo/lib/python3.10/site-packages/urllib3/connectionpool.py:1045: InsecureRequestWarning: Unverified HTTPS request is being made to host 'api.weixin.qq.com'. Adding certificate verification is strongly advised. See: https://urllib3.readthedocs.io/en/1.26.x/advanced-usage.html#ssl-warnings
  warnings.warn(
/home/ubuntu/virtualenv/vulndemo/lib/python3.10/site-packages/urllib3/connectionpool.py:1045: InsecureRequestWarning: Unverified HTTPS request is being made to host 'api.weixin.qq.com'. Adding certificate verification is strongly advised. See: https://urllib3.readthedocs.io/en/1.26.x/advanced-usage.html#ssl-warnings
  warnings.warn(
/home/ubuntu/virtualenv/vulndemo/lib/python3.10/site-packages/urllib3/connectionpool.py:1045: InsecureRequestWarning: Unverified HTTPS request is being made to host 'api.weixin.qq.com'. Adding certificate verification is strongly advised. See: https://urllib3.readthedocs.io/en/1.26.x/advanced-usage.html#ssl-warnings
  warnings.warn(
/home/ubuntu/virtualenv/vulndemo/lib/python3.10/site-packages/urllib3/connectionpool.py:1045: InsecureRequestWarning: Unverified HTTPS request is being made to host 'api.weixin.qq.com'. Adding certificate verification is strongly advised. See: https://urllib3.readthedocs.io/en/1.26.x/advanced-usage.html#ssl-warnings
  warnings.warn(
/home/ubuntu/virtualenv/vulndemo/lib/python3.10/site-packages/urllib3/connectionpool.py:1045: InsecureRequestWarning: Unverified HTTPS request is being made to host 'api.weixin.qq.com'. Adding certificate verification is strongly advised. See: https://urllib3.readthedocs.io/en/1.26.x/advanced-usage.html#ssl-warnings
  warnings.warn(
/home/ubuntu/virtualenv/vulndemo/lib/python3.10/site-packages/urllib3/connectionpool.py:1045: InsecureRequestWarning: Unverified HTTPS request is being made to host 'api.weixin.qq.com'. Adding certificate verification is strongly advised. See: https://urllib3.readthedocs.io/en/1.26.x/advanced-usage.html#ssl-warnings
  warnings.warn(
/home/ubuntu/virtualenv/vulndemo/lib/python3.10/site-packages/urllib3/connectionpool.py:1045: InsecureRequestWarning: Unverified HTTPS request is being made to host 'api.weixin.qq.com'. Adding certificate verification is strongly advised. See: https://urllib3.readthedocs.io/en/1.26.x/advanced-usage.html#ssl-warnings
  warnings.warn(
/home/ubuntu/virtualenv/vulndemo/lib/python3.10/site-packages/urllib3/connectionpool.py:1045: InsecureRequestWarning: Unverified HTTPS request is being made to host 'api.weixin.qq.com'. Adding certificate verification is strongly advised. See: https://urllib3.readthedocs.io/en/1.26.x/advanced-usage.html#ssl-warnings
  warnings.warn(
/home/ubuntu/virtualenv/vulndemo/lib/python3.10/site-packages/urllib3/connectionpool.py:1045: InsecureRequestWarning: Unverified HTTPS request is being made to host 'api.weixin.qq.com'. Adding certificate verification is strongly advised. See: https://urllib3.readthedocs.io/en/1.26.x/advanced-usage.html#ssl-warnings
  warnings.warn(
/home/ubuntu/virtualenv/vulndemo/lib/python3.10/site-packages/urllib3/connectionpool.py:1045: InsecureRequestWarning: Unverified HTTPS request is being made to host 'api.weixin.qq.com'. Adding certificate verification is strongly advised. See: https://urllib3.readthedocs.io/en/1.26.x/advanced-usage.html#ssl-warnings
  warnings.warn(
/home/ubuntu/virtualenv/vulndemo/lib/python3.10/site-packages/urllib3/connectionpool.py:1045: InsecureRequestWarning: Unverified HTTPS request is being made to host 'api.weixin.qq.com'. Adding certificate verification is strongly advised. See: https://urllib3.readthedocs.io/en/1.26.x/advanced-usage.html#ssl-warnings
  warnings.warn(
[2022-12-02 15:36:24 +0800] [814735] [DEBUG] Current configuration:
  config: /home/ubuntu/work/gconfig.py
  wsgi_app: None
  bind: ['0.0.0.0:5000']
  backlog: 2048
  workers: 4
  worker_class: gevent
  threads: 1
  worker_connections: 1000
  max_requests: 0
  max_requests_jitter: 0
  timeout: 30
  graceful_timeout: 30
  keepalive: 2
  limit_request_line: 4094
  limit_request_fields: 100
  limit_request_field_size: 8190
  reload: False
  reload_engine: auto
  reload_extra_files: []
  spew: False
  check_config: False
  print_config: False
  preload_app: False
  sendfile: None
  reuse_port: False
  chdir: /home/ubuntu/work
  daemon: False
  raw_env: []
  pidfile: log/gunicorn.pid
  worker_tmp_dir: None
  user: 0
  group: 0
  umask: 0
  initgroups: False
  tmp_upload_dir: None
  secure_scheme_headers: {'X-FORWARDED-PROTOCOL': 'ssl', 'X-FORWARDED-PROTO': 'https', 'X-FORWARDED-SSL': 'on'}
  forwarded_allow_ips: ['127.0.0.1']
  accesslog: None
  disable_redirect_access_to_syslog: False
  access_log_format: %(h)s %(l)s %(u)s %(t)s "%(r)s" %(s)s %(b)s "%(f)s" "%(a)s"
  errorlog: -
  loglevel: debug
  capture_output: False
  logger_class: gunicorn.glogging.Logger
  logconfig: None
  logconfig_dict: {}
  syslog_addr: udp://localhost:514
  syslog: False
  syslog_prefix: None
  syslog_facility: user
  enable_stdio_inheritance: False
  statsd_host: None
  dogstatsd_tags: 
  statsd_prefix: 
  proc_name: None
  default_proc_name: app:app
  pythonpath: None
  paste: None
  on_starting: <function OnStarting.on_starting at 0x7f01e51364d0>
  on_reload: <function OnReload.on_reload at 0x7f01e51365f0>
  when_ready: <function WhenReady.when_ready at 0x7f01e5136710>
  pre_fork: <function Prefork.pre_fork at 0x7f01e5136830>
  post_fork: <function Postfork.post_fork at 0x7f01e5136950>
  post_worker_init: <function PostWorkerInit.post_worker_init at 0x7f01e5136a70>
  worker_int: <function WorkerInt.worker_int at 0x7f01e5136b90>
  worker_abort: <function WorkerAbort.worker_abort at 0x7f01e5136cb0>
  pre_exec: <function PreExec.pre_exec at 0x7f01e5136dd0>
  pre_request: <function PreRequest.pre_request at 0x7f01e5136ef0>
  post_request: <function PostRequest.post_request at 0x7f01e5136f80>
  child_exit: <function ChildExit.child_exit at 0x7f01e51370a0>
  worker_exit: <function WorkerExit.worker_exit at 0x7f01e51371c0>
  nworkers_changed: <function NumWorkersChanged.nworkers_changed at 0x7f01e51372e0>
  on_exit: <function OnExit.on_exit at 0x7f01e5137400>
  proxy_protocol: False
  proxy_allow_ips: ['127.0.0.1']
  keyfile: None
  certfile: None
  ssl_version: 2
  cert_reqs: 0
  ca_certs: None
  suppress_ragged_eofs: True
  do_handshake_on_connect: False
  ciphers: None
  raw_paste_global_conf: []
  strip_header_spaces: False
[2022-12-02 15:36:24 +0800] [814735] [INFO] Starting gunicorn 20.1.0
[2022-12-02 15:36:24 +0800] [814735] [DEBUG] Arbiter booted
[2022-12-02 15:36:24 +0800] [814735] [INFO] Listening at: http://0.0.0.0:5000 (814735)
[2022-12-02 15:36:24 +0800] [814735] [INFO] Using worker: gevent
[2022-12-02 15:36:24 +0800] [814736] [INFO] Booting worker with pid: 814736
[2022-12-02 15:36:24 +0800] [814737] [INFO] Booting worker with pid: 814737
[2022-12-02 15:36:24 +0800] [814738] [INFO] Booting worker with pid: 814738
[2022-12-02 15:36:24 +0800] [814739] [INFO] Booting worker with pid: 814739
[2022-12-02 15:36:24 +0800] [814735] [DEBUG] 4 workers
[2022-12-02 15:36:24 +0800] [814736] [ERROR] Exception in worker process
Traceback (most recent call last):
  File "/home/ubuntu/virtualenv/vulndemo/lib/python3.10/site-packages/gunicorn/arbiter.py", line 589, in spawn_worker
    worker.init_process()
  File "/home/ubuntu/virtualenv/vulndemo/lib/python3.10/site-packages/gunicorn/workers/ggevent.py", line 146, in init_process
    super().init_process()
  File "/home/ubuntu/virtualenv/vulndemo/lib/python3.10/site-packages/gunicorn/workers/base.py", line 134, in init_process
    self.load_wsgi()
  File "/home/ubuntu/virtualenv/vulndemo/lib/python3.10/site-packages/gunicorn/workers/base.py", line 146, in load_wsgi
    self.wsgi = self.app.wsgi()
  File "/home/ubuntu/virtualenv/vulndemo/lib/python3.10/site-packages/gunicorn/app/base.py", line 67, in wsgi
    self.callable = self.load()
  File "/home/ubuntu/virtualenv/vulndemo/lib/python3.10/site-packages/gunicorn/app/wsgiapp.py", line 58, in load
    return self.load_wsgiapp()
  File "/home/ubuntu/virtualenv/vulndemo/lib/python3.10/site-packages/gunicorn/app/wsgiapp.py", line 48, in load_wsgiapp
    return util.import_app(self.app_uri)
  File "/home/ubuntu/virtualenv/vulndemo/lib/python3.10/site-packages/gunicorn/util.py", line 359, in import_app
    mod = importlib.import_module(module)
  File "/usr/lib/python3.10/importlib/__init__.py", line 126, in import_module
    return _bootstrap._gcd_import(name[level:], package, level)
  File "<frozen importlib._bootstrap>", line 1050, in _gcd_import
  File "<frozen importlib._bootstrap>", line 1027, in _find_and_load
  File "<frozen importlib._bootstrap>", line 1006, in _find_and_load_unlocked
  File "<frozen importlib._bootstrap>", line 688, in _load_unlocked
  File "<frozen importlib._bootstrap_external>", line 883, in exec_module
  File "<frozen importlib._bootstrap>", line 241, in _call_with_frames_removed
  File "/home/ubuntu/work/app.py", line 7, in <module>
    from flask_cors import CORS, cross_origin
ModuleNotFoundError: No module named 'flask_cors'
[2022-12-02 15:36:24 +0800] [814736] [INFO] Worker exiting (pid: 814736)
[2022-12-02 15:36:24 +0800] [814737] [ERROR] Exception in worker process
Traceback (most recent call last):
  File "/home/ubuntu/virtualenv/vulndemo/lib/python3.10/site-packages/gunicorn/arbiter.py", line 589, in spawn_worker
    worker.init_process()
  File "/home/ubuntu/virtualenv/vulndemo/lib/python3.10/site-packages/gunicorn/workers/ggevent.py", line 146, in init_process
    super().init_process()
  File "/home/ubuntu/virtualenv/vulndemo/lib/python3.10/site-packages/gunicorn/workers/base.py", line 134, in init_process
    self.load_wsgi()
  File "/home/ubuntu/virtualenv/vulndemo/lib/python3.10/site-packages/gunicorn/workers/base.py", line 146, in load_wsgi
    self.wsgi = self.app.wsgi()
  File "/home/ubuntu/virtualenv/vulndemo/lib/python3.10/site-packages/gunicorn/app/base.py", line 67, in wsgi
    self.callable = self.load()
  File "/home/ubuntu/virtualenv/vulndemo/lib/python3.10/site-packages/gunicorn/app/wsgiapp.py", line 58, in load
    return self.load_wsgiapp()
  File "/home/ubuntu/virtualenv/vulndemo/lib/python3.10/site-packages/gunicorn/app/wsgiapp.py", line 48, in load_wsgiapp
    return util.import_app(self.app_uri)
  File "/home/ubuntu/virtualenv/vulndemo/lib/python3.10/site-packages/gunicorn/util.py", line 359, in import_app
    mod = importlib.import_module(module)
  File "/usr/lib/python3.10/importlib/__init__.py", line 126, in import_module
    return _bootstrap._gcd_import(name[level:], package, level)
  File "<frozen importlib._bootstrap>", line 1050, in _gcd_import
  File "<frozen importlib._bootstrap>", line 1027, in _find_and_load
  File "<frozen importlib._bootstrap>", line 1006, in _find_and_load_unlocked
  File "<frozen importlib._bootstrap>", line 688, in _load_unlocked
  File "<frozen importlib._bootstrap_external>", line 883, in exec_module
  File "<frozen importlib._bootstrap>", line 241, in _call_with_frames_removed
  File "/home/ubuntu/work/app.py", line 7, in <module>
    from flask_cors import CORS, cross_origin
ModuleNotFoundError: No module named 'flask_cors'
[2022-12-02 15:36:24 +0800] [814737] [INFO] Worker exiting (pid: 814737)
[2022-12-02 15:36:24 +0800] [814738] [ERROR] Exception in worker process
Traceback (most recent call last):
  File "/home/ubuntu/virtualenv/vulndemo/lib/python3.10/site-packages/gunicorn/arbiter.py", line 589, in spawn_worker
    worker.init_process()
  File "/home/ubuntu/virtualenv/vulndemo/lib/python3.10/site-packages/gunicorn/workers/ggevent.py", line 146, in init_process
    super().init_process()
  File "/home/ubuntu/virtualenv/vulndemo/lib/python3.10/site-packages/gunicorn/workers/base.py", line 134, in init_process
    self.load_wsgi()
  File "/home/ubuntu/virtualenv/vulndemo/lib/python3.10/site-packages/gunicorn/workers/base.py", line 146, in load_wsgi
    self.wsgi = self.app.wsgi()
  File "/home/ubuntu/virtualenv/vulndemo/lib/python3.10/site-packages/gunicorn/app/base.py", line 67, in wsgi
    self.callable = self.load()
  File "/home/ubuntu/virtualenv/vulndemo/lib/python3.10/site-packages/gunicorn/app/wsgiapp.py", line 58, in load
    return self.load_wsgiapp()
  File "/home/ubuntu/virtualenv/vulndemo/lib/python3.10/site-packages/gunicorn/app/wsgiapp.py", line 48, in load_wsgiapp
    return util.import_app(self.app_uri)
  File "/home/ubuntu/virtualenv/vulndemo/lib/python3.10/site-packages/gunicorn/util.py", line 359, in import_app
    mod = importlib.import_module(module)
  File "/usr/lib/python3.10/importlib/__init__.py", line 126, in import_module
    return _bootstrap._gcd_import(name[level:], package, level)
  File "<frozen importlib._bootstrap>", line 1050, in _gcd_import
  File "<frozen importlib._bootstrap>", line 1027, in _find_and_load
  File "<frozen importlib._bootstrap>", line 1006, in _find_and_load_unlocked
  File "<frozen importlib._bootstrap>", line 688, in _load_unlocked
  File "<frozen importlib._bootstrap_external>", line 883, in exec_module
  File "<frozen importlib._bootstrap>", line 241, in _call_with_frames_removed
  File "/home/ubuntu/work/app.py", line 7, in <module>
    from flask_cors import CORS, cross_origin
ModuleNotFoundError: No module named 'flask_cors'
[2022-12-02 15:36:24 +0800] [814738] [INFO] Worker exiting (pid: 814738)
[2022-12-02 15:36:24 +0800] [814739] [ERROR] Exception in worker process
Traceback (most recent call last):
  File "/home/ubuntu/virtualenv/vulndemo/lib/python3.10/site-packages/gunicorn/arbiter.py", line 589, in spawn_worker
    worker.init_process()
  File "/home/ubuntu/virtualenv/vulndemo/lib/python3.10/site-packages/gunicorn/workers/ggevent.py", line 146, in init_process
    super().init_process()
  File "/home/ubuntu/virtualenv/vulndemo/lib/python3.10/site-packages/gunicorn/workers/base.py", line 134, in init_process
    self.load_wsgi()
  File "/home/ubuntu/virtualenv/vulndemo/lib/python3.10/site-packages/gunicorn/workers/base.py", line 146, in load_wsgi
    self.wsgi = self.app.wsgi()
  File "/home/ubuntu/virtualenv/vulndemo/lib/python3.10/site-packages/gunicorn/app/base.py", line 67, in wsgi
    self.callable = self.load()
  File "/home/ubuntu/virtualenv/vulndemo/lib/python3.10/site-packages/gunicorn/app/wsgiapp.py", line 58, in load
    return self.load_wsgiapp()
  File "/home/ubuntu/virtualenv/vulndemo/lib/python3.10/site-packages/gunicorn/app/wsgiapp.py", line 48, in load_wsgiapp
    return util.import_app(self.app_uri)
  File "/home/ubuntu/virtualenv/vulndemo/lib/python3.10/site-packages/gunicorn/util.py", line 359, in import_app
    mod = importlib.import_module(module)
  File "/usr/lib/python3.10/importlib/__init__.py", line 126, in import_module
    return _bootstrap._gcd_import(name[level:], package, level)
  File "<frozen importlib._bootstrap>", line 1050, in _gcd_import
  File "<frozen importlib._bootstrap>", line 1027, in _find_and_load
  File "<frozen importlib._bootstrap>", line 1006, in _find_and_load_unlocked
  File "<frozen importlib._bootstrap>", line 688, in _load_unlocked
  File "<frozen importlib._bootstrap_external>", line 883, in exec_module
  File "<frozen importlib._bootstrap>", line 241, in _call_with_frames_removed
  File "/home/ubuntu/work/app.py", line 7, in <module>
    from flask_cors import CORS, cross_origin
ModuleNotFoundError: No module named 'flask_cors'
[2022-12-02 15:36:24 +0800] [814739] [INFO] Worker exiting (pid: 814739)
Traceback (most recent call last):
  File "src/gevent/greenlet.py", line 908, in gevent._gevent_cgreenlet.Greenlet.run
  File "/home/ubuntu/virtualenv/vulndemo/lib/python3.10/site-packages/gunicorn/arbiter.py", line 242, in handle_chld
    self.reap_workers()
  File "/home/ubuntu/virtualenv/vulndemo/lib/python3.10/site-packages/gunicorn/arbiter.py", line 525, in reap_workers
    raise HaltServer(reason, self.WORKER_BOOT_ERROR)
gunicorn.errors.HaltServer: <HaltServer 'Worker failed to boot.' 3>
2022-12-02T07:36:24Z <Greenlet at 0x7f01e5cb1580: <bound method Arbiter.handle_chld of <gunicorn.arbiter.Arbiter object at 0x7f01e495ada0>>(17, None)> failed with HaltServer

Traceback (most recent call last):
  File "src/gevent/greenlet.py", line 908, in gevent._gevent_cgreenlet.Greenlet.run
  File "/home/ubuntu/virtualenv/vulndemo/lib/python3.10/site-packages/gunicorn/arbiter.py", line 242, in handle_chld
    self.reap_workers()
  File "/home/ubuntu/virtualenv/vulndemo/lib/python3.10/site-packages/gunicorn/arbiter.py", line 525, in reap_workers
    raise HaltServer(reason, self.WORKER_BOOT_ERROR)
gunicorn.errors.HaltServer: <HaltServer 'Worker failed to boot.' 3>
2022-12-02T07:36:24Z <Greenlet at 0x7f01e5cb1580: <bound method Arbiter.handle_chld of <gunicorn.arbiter.Arbiter object at 0x7f01e495ada0>>(17, None)> failed with HaltServer

Traceback (most recent call last):
  File "src/gevent/greenlet.py", line 908, in gevent._gevent_cgreenlet.Greenlet.run
  File "/home/ubuntu/virtualenv/vulndemo/lib/python3.10/site-packages/gunicorn/arbiter.py", line 242, in handle_chld
    self.reap_workers()
  File "/home/ubuntu/virtualenv/vulndemo/lib/python3.10/site-packages/gunicorn/arbiter.py", line 525, in reap_workers
    raise HaltServer(reason, self.WORKER_BOOT_ERROR)
gunicorn.errors.HaltServer: <HaltServer 'Worker failed to boot.' 3>
2022-12-02T07:36:24Z <Greenlet at 0x7f01e5cb1580: <bound method Arbiter.handle_chld of <gunicorn.arbiter.Arbiter object at 0x7f01e495ada0>>(17, None)> failed with HaltServer

Traceback (most recent call last):
  File "src/gevent/greenlet.py", line 908, in gevent._gevent_cgreenlet.Greenlet.run
  File "/home/ubuntu/virtualenv/vulndemo/lib/python3.10/site-packages/gunicorn/arbiter.py", line 242, in handle_chld
    self.reap_workers()
  File "/home/ubuntu/virtualenv/vulndemo/lib/python3.10/site-packages/gunicorn/arbiter.py", line 525, in reap_workers
    raise HaltServer(reason, self.WORKER_BOOT_ERROR)
gunicorn.errors.HaltServer: <HaltServer 'Worker failed to boot.' 3>
2022-12-02T07:36:24Z <Greenlet at 0x7f01e5cb1580: <bound method Arbiter.handle_chld of <gunicorn.arbiter.Arbiter object at 0x7f01e495ada0>>(17, None)> failed with HaltServer

[2022-12-02 15:36:54 +0800] [814735] [CRITICAL] WORKER TIMEOUT (pid:814736)
[2022-12-02 15:36:54 +0800] [814735] [CRITICAL] WORKER TIMEOUT (pid:814737)
[2022-12-02 15:36:54 +0800] [814735] [CRITICAL] WORKER TIMEOUT (pid:814738)
[2022-12-02 15:36:54 +0800] [814735] [CRITICAL] WORKER TIMEOUT (pid:814739)
[2022-12-02 15:36:54 +0800] [814802] [INFO] Booting worker with pid: 814802
[2022-12-02 15:36:54 +0800] [814803] [INFO] Booting worker with pid: 814803
[2022-12-02 15:36:54 +0800] [814802] [ERROR] Exception in worker process
Traceback (most recent call last):
  File "/home/ubuntu/virtualenv/vulndemo/lib/python3.10/site-packages/gunicorn/arbiter.py", line 589, in spawn_worker
    worker.init_process()
  File "/home/ubuntu/virtualenv/vulndemo/lib/python3.10/site-packages/gunicorn/workers/ggevent.py", line 146, in init_process
    super().init_process()
  File "/home/ubuntu/virtualenv/vulndemo/lib/python3.10/site-packages/gunicorn/workers/base.py", line 134, in init_process
    self.load_wsgi()
  File "/home/ubuntu/virtualenv/vulndemo/lib/python3.10/site-packages/gunicorn/workers/base.py", line 146, in load_wsgi
    self.wsgi = self.app.wsgi()
  File "/home/ubuntu/virtualenv/vulndemo/lib/python3.10/site-packages/gunicorn/app/base.py", line 67, in wsgi
    self.callable = self.load()
  File "/home/ubuntu/virtualenv/vulndemo/lib/python3.10/site-packages/gunicorn/app/wsgiapp.py", line 58, in load
    return self.load_wsgiapp()
  File "/home/ubuntu/virtualenv/vulndemo/lib/python3.10/site-packages/gunicorn/app/wsgiapp.py", line 48, in load_wsgiapp
    return util.import_app(self.app_uri)
  File "/home/ubuntu/virtualenv/vulndemo/lib/python3.10/site-packages/gunicorn/util.py", line 359, in import_app
    mod = importlib.import_module(module)
  File "/usr/lib/python3.10/importlib/__init__.py", line 126, in import_module
    return _bootstrap._gcd_import(name[level:], package, level)
  File "<frozen importlib._bootstrap>", line 1050, in _gcd_import
  File "<frozen importlib._bootstrap>", line 1027, in _find_and_load
  File "<frozen importlib._bootstrap>", line 1006, in _find_and_load_unlocked
  File "<frozen importlib._bootstrap>", line 688, in _load_unlocked
  File "<frozen importlib._bootstrap_external>", line 883, in exec_module
  File "<frozen importlib._bootstrap>", line 241, in _call_with_frames_removed
  File "/home/ubuntu/work/app.py", line 7, in <module>
    from flask_cors import CORS, cross_origin
ModuleNotFoundError: No module named 'flask_cors'
[2022-12-02 15:36:54 +0800] [814802] [INFO] Worker exiting (pid: 814802)
[2022-12-02 15:36:54 +0800] [814805] [INFO] Booting worker with pid: 814805
[2022-12-02 15:36:54 +0800] [814806] [INFO] Booting worker with pid: 814806
Traceback (most recent call last):
  File "src/gevent/greenlet.py", line 908, in gevent._gevent_cgreenlet.Greenlet.run
  File "/home/ubuntu/virtualenv/vulndemo/lib/python3.10/site-packages/gunicorn/arbiter.py", line 242, in handle_chld
    self.reap_workers()
  File "/home/ubuntu/virtualenv/vulndemo/lib/python3.10/site-packages/gunicorn/arbiter.py", line 525, in reap_workers
    raise HaltServer(reason, self.WORKER_BOOT_ERROR)
gunicorn.errors.HaltServer: <HaltServer 'Worker failed to boot.' 3>
2022-12-02T07:36:54Z <Greenlet at 0x7f01e5cb1580: <bound method Arbiter.handle_chld of <gunicorn.arbiter.Arbiter object at 0x7f01e495ada0>>(17, None)> failed with HaltServer

[2022-12-02 15:36:54 +0800] [814803] [ERROR] Exception in worker process
Traceback (most recent call last):
  File "/home/ubuntu/virtualenv/vulndemo/lib/python3.10/site-packages/gunicorn/arbiter.py", line 589, in spawn_worker
    worker.init_process()
  File "/home/ubuntu/virtualenv/vulndemo/lib/python3.10/site-packages/gunicorn/workers/ggevent.py", line 146, in init_process
    super().init_process()
  File "/home/ubuntu/virtualenv/vulndemo/lib/python3.10/site-packages/gunicorn/workers/base.py", line 134, in init_process
    self.load_wsgi()
  File "/home/ubuntu/virtualenv/vulndemo/lib/python3.10/site-packages/gunicorn/workers/base.py", line 146, in load_wsgi
    self.wsgi = self.app.wsgi()
  File "/home/ubuntu/virtualenv/vulndemo/lib/python3.10/site-packages/gunicorn/app/base.py", line 67, in wsgi
    self.callable = self.load()
  File "/home/ubuntu/virtualenv/vulndemo/lib/python3.10/site-packages/gunicorn/app/wsgiapp.py", line 58, in load
    return self.load_wsgiapp()
  File "/home/ubuntu/virtualenv/vulndemo/lib/python3.10/site-packages/gunicorn/app/wsgiapp.py", line 48, in load_wsgiapp
    return util.import_app(self.app_uri)
  File "/home/ubuntu/virtualenv/vulndemo/lib/python3.10/site-packages/gunicorn/util.py", line 359, in import_app
    mod = importlib.import_module(module)
  File "/usr/lib/python3.10/importlib/__init__.py", line 126, in import_module
    return _bootstrap._gcd_import(name[level:], package, level)
  File "<frozen importlib._bootstrap>", line 1050, in _gcd_import
  File "<frozen importlib._bootstrap>", line 1027, in _find_and_load
  File "<frozen importlib._bootstrap>", line 1006, in _find_and_load_unlocked
  File "<frozen importlib._bootstrap>", line 688, in _load_unlocked
  File "<frozen importlib._bootstrap_external>", line 883, in exec_module
  File "<frozen importlib._bootstrap>", line 241, in _call_with_frames_removed
  File "/home/ubuntu/work/app.py", line 7, in <module>
    from flask_cors import CORS, cross_origin
ModuleNotFoundError: No module named 'flask_cors'
[2022-12-02 15:36:54 +0800] [814803] [INFO] Worker exiting (pid: 814803)
[2022-12-02 15:36:54 +0800] [814805] [ERROR] Exception in worker process
Traceback (most recent call last):
  File "/home/ubuntu/virtualenv/vulndemo/lib/python3.10/site-packages/gunicorn/arbiter.py", line 589, in spawn_worker
    worker.init_process()
  File "/home/ubuntu/virtualenv/vulndemo/lib/python3.10/site-packages/gunicorn/workers/ggevent.py", line 146, in init_process
    super().init_process()
  File "/home/ubuntu/virtualenv/vulndemo/lib/python3.10/site-packages/gunicorn/workers/base.py", line 134, in init_process
    self.load_wsgi()
  File "/home/ubuntu/virtualenv/vulndemo/lib/python3.10/site-packages/gunicorn/workers/base.py", line 146, in load_wsgi
    self.wsgi = self.app.wsgi()
  File "/home/ubuntu/virtualenv/vulndemo/lib/python3.10/site-packages/gunicorn/app/base.py", line 67, in wsgi
    self.callable = self.load()
  File "/home/ubuntu/virtualenv/vulndemo/lib/python3.10/site-packages/gunicorn/app/wsgiapp.py", line 58, in load
    return self.load_wsgiapp()
  File "/home/ubuntu/virtualenv/vulndemo/lib/python3.10/site-packages/gunicorn/app/wsgiapp.py", line 48, in load_wsgiapp
    return util.import_app(self.app_uri)
  File "/home/ubuntu/virtualenv/vulndemo/lib/python3.10/site-packages/gunicorn/util.py", line 359, in import_app
    mod = importlib.import_module(module)
  File "/usr/lib/python3.10/importlib/__init__.py", line 126, in import_module
    return _bootstrap._gcd_import(name[level:], package, level)
  File "<frozen importlib._bootstrap>", line 1050, in _gcd_import
  File "<frozen importlib._bootstrap>", line 1027, in _find_and_load
  File "<frozen importlib._bootstrap>", line 1006, in _find_and_load_unlocked
  File "<frozen importlib._bootstrap>", line 688, in _load_unlocked
  File "<frozen importlib._bootstrap_external>", line 883, in exec_module
  File "<frozen importlib._bootstrap>", line 241, in _call_with_frames_removed
  File "/home/ubuntu/work/app.py", line 7, in <module>
    from flask_cors import CORS, cross_origin
ModuleNotFoundError: No module named 'flask_cors'
[2022-12-02 15:36:54 +0800] [814805] [INFO] Worker exiting (pid: 814805)
Traceback (most recent call last):
  File "src/gevent/greenlet.py", line 908, in gevent._gevent_cgreenlet.Greenlet.run
  File "/home/ubuntu/virtualenv/vulndemo/lib/python3.10/site-packages/gunicorn/arbiter.py", line 242, in handle_chld
    self.reap_workers()
  File "/home/ubuntu/virtualenv/vulndemo/lib/python3.10/site-packages/gunicorn/arbiter.py", line 525, in reap_workers
    raise HaltServer(reason, self.WORKER_BOOT_ERROR)
gunicorn.errors.HaltServer: <HaltServer 'Worker failed to boot.' 3>
2022-12-02T07:36:54Z <Greenlet at 0x7f01e5cb1580: <bound method Arbiter.handle_chld of <gunicorn.arbiter.Arbiter object at 0x7f01e495ada0>>(17, None)> failed with HaltServer

Traceback (most recent call last):
  File "src/gevent/greenlet.py", line 908, in gevent._gevent_cgreenlet.Greenlet.run
  File "/home/ubuntu/virtualenv/vulndemo/lib/python3.10/site-packages/gunicorn/arbiter.py", line 242, in handle_chld
    self.reap_workers()
  File "/home/ubuntu/virtualenv/vulndemo/lib/python3.10/site-packages/gunicorn/arbiter.py", line 525, in reap_workers
    raise HaltServer(reason, self.WORKER_BOOT_ERROR)
gunicorn.errors.HaltServer: <HaltServer 'Worker failed to boot.' 3>
2022-12-02T07:36:54Z <Greenlet at 0x7f01e5cb1580: <bound method Arbiter.handle_chld of <gunicorn.arbiter.Arbiter object at 0x7f01e495ada0>>(17, None)> failed with HaltServer

[2022-12-02 15:36:54 +0800] [814806] [ERROR] Exception in worker process
Traceback (most recent call last):
  File "/home/ubuntu/virtualenv/vulndemo/lib/python3.10/site-packages/gunicorn/arbiter.py", line 589, in spawn_worker
    worker.init_process()
  File "/home/ubuntu/virtualenv/vulndemo/lib/python3.10/site-packages/gunicorn/workers/ggevent.py", line 146, in init_process
    super().init_process()
  File "/home/ubuntu/virtualenv/vulndemo/lib/python3.10/site-packages/gunicorn/workers/base.py", line 134, in init_process
    self.load_wsgi()
  File "/home/ubuntu/virtualenv/vulndemo/lib/python3.10/site-packages/gunicorn/workers/base.py", line 146, in load_wsgi
    self.wsgi = self.app.wsgi()
  File "/home/ubuntu/virtualenv/vulndemo/lib/python3.10/site-packages/gunicorn/app/base.py", line 67, in wsgi
    self.callable = self.load()
  File "/home/ubuntu/virtualenv/vulndemo/lib/python3.10/site-packages/gunicorn/app/wsgiapp.py", line 58, in load
    return self.load_wsgiapp()
  File "/home/ubuntu/virtualenv/vulndemo/lib/python3.10/site-packages/gunicorn/app/wsgiapp.py", line 48, in load_wsgiapp
    return util.import_app(self.app_uri)
  File "/home/ubuntu/virtualenv/vulndemo/lib/python3.10/site-packages/gunicorn/util.py", line 359, in import_app
    mod = importlib.import_module(module)
  File "/usr/lib/python3.10/importlib/__init__.py", line 126, in import_module
    return _bootstrap._gcd_import(name[level:], package, level)
  File "<frozen importlib._bootstrap>", line 1050, in _gcd_import
  File "<frozen importlib._bootstrap>", line 1027, in _find_and_load
  File "<frozen importlib._bootstrap>", line 1006, in _find_and_load_unlocked
  File "<frozen importlib._bootstrap>", line 688, in _load_unlocked
  File "<frozen importlib._bootstrap_external>", line 883, in exec_module
  File "<frozen importlib._bootstrap>", line 241, in _call_with_frames_removed
  File "/home/ubuntu/work/app.py", line 7, in <module>
    from flask_cors import CORS, cross_origin
ModuleNotFoundError: No module named 'flask_cors'
[2022-12-02 15:36:54 +0800] [814806] [INFO] Worker exiting (pid: 814806)
Traceback (most recent call last):
  File "src/gevent/greenlet.py", line 908, in gevent._gevent_cgreenlet.Greenlet.run
  File "/home/ubuntu/virtualenv/vulndemo/lib/python3.10/site-packages/gunicorn/arbiter.py", line 242, in handle_chld
    self.reap_workers()
  File "/home/ubuntu/virtualenv/vulndemo/lib/python3.10/site-packages/gunicorn/arbiter.py", line 525, in reap_workers
    raise HaltServer(reason, self.WORKER_BOOT_ERROR)
gunicorn.errors.HaltServer: <HaltServer 'Worker failed to boot.' 3>
2022-12-02T07:36:54Z <Greenlet at 0x7f01e5cb1580: <bound method Arbiter.handle_chld of <gunicorn.arbiter.Arbiter object at 0x7f01e495ada0>>(17, None)> failed with HaltServer

[2022-12-02 15:37:24 +0800] [814735] [CRITICAL] WORKER TIMEOUT (pid:814802)
[2022-12-02 15:37:24 +0800] [814735] [CRITICAL] WORKER TIMEOUT (pid:814803)
[2022-12-02 15:37:24 +0800] [814735] [CRITICAL] WORKER TIMEOUT (pid:814805)
[2022-12-02 15:37:24 +0800] [814735] [CRITICAL] WORKER TIMEOUT (pid:814806)
[2022-12-02 15:37:24 +0800] [814914] [INFO] Booting worker with pid: 814914
[2022-12-02 15:37:24 +0800] [814915] [INFO] Booting worker with pid: 814915
[2022-12-02 15:37:24 +0800] [814916] [INFO] Booting worker with pid: 814916
[2022-12-02 15:37:24 +0800] [814917] [INFO] Booting worker with pid: 814917
[2022-12-02 15:37:24 +0800] [814914] [ERROR] Exception in worker process
Traceback (most recent call last):
  File "/home/ubuntu/virtualenv/vulndemo/lib/python3.10/site-packages/gunicorn/arbiter.py", line 589, in spawn_worker
    worker.init_process()
  File "/home/ubuntu/virtualenv/vulndemo/lib/python3.10/site-packages/gunicorn/workers/ggevent.py", line 146, in init_process
    super().init_process()
  File "/home/ubuntu/virtualenv/vulndemo/lib/python3.10/site-packages/gunicorn/workers/base.py", line 134, in init_process
    self.load_wsgi()
  File "/home/ubuntu/virtualenv/vulndemo/lib/python3.10/site-packages/gunicorn/workers/base.py", line 146, in load_wsgi
    self.wsgi = self.app.wsgi()
  File "/home/ubuntu/virtualenv/vulndemo/lib/python3.10/site-packages/gunicorn/app/base.py", line 67, in wsgi
    self.callable = self.load()
  File "/home/ubuntu/virtualenv/vulndemo/lib/python3.10/site-packages/gunicorn/app/wsgiapp.py", line 58, in load
    return self.load_wsgiapp()
  File "/home/ubuntu/virtualenv/vulndemo/lib/python3.10/site-packages/gunicorn/app/wsgiapp.py", line 48, in load_wsgiapp
    return util.import_app(self.app_uri)
  File "/home/ubuntu/virtualenv/vulndemo/lib/python3.10/site-packages/gunicorn/util.py", line 359, in import_app
    mod = importlib.import_module(module)
  File "/usr/lib/python3.10/importlib/__init__.py", line 126, in import_module
    return _bootstrap._gcd_import(name[level:], package, level)
  File "<frozen importlib._bootstrap>", line 1050, in _gcd_import
  File "<frozen importlib._bootstrap>", line 1027, in _find_and_load
  File "<frozen importlib._bootstrap>", line 1006, in _find_and_load_unlocked
  File "<frozen importlib._bootstrap>", line 688, in _load_unlocked
  File "<frozen importlib._bootstrap_external>", line 883, in exec_module
  File "<frozen importlib._bootstrap>", line 241, in _call_with_frames_removed
  File "/home/ubuntu/work/app.py", line 7, in <module>
    from flask_cors import CORS, cross_origin
ModuleNotFoundError: No module named 'flask_cors'
[2022-12-02 15:37:24 +0800] [814914] [INFO] Worker exiting (pid: 814914)
[2022-12-02 15:37:25 +0800] [814915] [ERROR] Exception in worker process
Traceback (most recent call last):
  File "/home/ubuntu/virtualenv/vulndemo/lib/python3.10/site-packages/gunicorn/arbiter.py", line 589, in spawn_worker
    worker.init_process()
  File "/home/ubuntu/virtualenv/vulndemo/lib/python3.10/site-packages/gunicorn/workers/ggevent.py", line 146, in init_process
    super().init_process()
  File "/home/ubuntu/virtualenv/vulndemo/lib/python3.10/site-packages/gunicorn/workers/base.py", line 134, in init_process
    self.load_wsgi()
  File "/home/ubuntu/virtualenv/vulndemo/lib/python3.10/site-packages/gunicorn/workers/base.py", line 146, in load_wsgi
    self.wsgi = self.app.wsgi()
  File "/home/ubuntu/virtualenv/vulndemo/lib/python3.10/site-packages/gunicorn/app/base.py", line 67, in wsgi
    self.callable = self.load()
  File "/home/ubuntu/virtualenv/vulndemo/lib/python3.10/site-packages/gunicorn/app/wsgiapp.py", line 58, in load
    return self.load_wsgiapp()
  File "/home/ubuntu/virtualenv/vulndemo/lib/python3.10/site-packages/gunicorn/app/wsgiapp.py", line 48, in load_wsgiapp
    return util.import_app(self.app_uri)
  File "/home/ubuntu/virtualenv/vulndemo/lib/python3.10/site-packages/gunicorn/util.py", line 359, in import_app
    mod = importlib.import_module(module)
  File "/usr/lib/python3.10/importlib/__init__.py", line 126, in import_module
    return _bootstrap._gcd_import(name[level:], package, level)
  File "<frozen importlib._bootstrap>", line 1050, in _gcd_import
  File "<frozen importlib._bootstrap>", line 1027, in _find_and_load
  File "<frozen importlib._bootstrap>", line 1006, in _find_and_load_unlocked
  File "<frozen importlib._bootstrap>", line 688, in _load_unlocked
  File "<frozen importlib._bootstrap_external>", line 883, in exec_module
  File "<frozen importlib._bootstrap>", line 241, in _call_with_frames_removed
  File "/home/ubuntu/work/app.py", line 7, in <module>
    from flask_cors import CORS, cross_origin
ModuleNotFoundError: No module named 'flask_cors'
[2022-12-02 15:37:25 +0800] [814915] [INFO] Worker exiting (pid: 814915)
Traceback (most recent call last):
  File "src/gevent/greenlet.py", line 908, in gevent._gevent_cgreenlet.Greenlet.run
  File "/home/ubuntu/virtualenv/vulndemo/lib/python3.10/site-packages/gunicorn/arbiter.py", line 242, in handle_chld
    self.reap_workers()
  File "/home/ubuntu/virtualenv/vulndemo/lib/python3.10/site-packages/gunicorn/arbiter.py", line 525, in reap_workers
    raise HaltServer(reason, self.WORKER_BOOT_ERROR)
gunicorn.errors.HaltServer: <HaltServer 'Worker failed to boot.' 3>
2022-12-02T07:37:25Z <Greenlet at 0x7f01e5cb1580: <bound method Arbiter.handle_chld of <gunicorn.arbiter.Arbiter object at 0x7f01e495ada0>>(17, None)> failed with HaltServer

[2022-12-02 15:37:25 +0800] [814917] [ERROR] Exception in worker process
Traceback (most recent call last):
  File "/home/ubuntu/virtualenv/vulndemo/lib/python3.10/site-packages/gunicorn/arbiter.py", line 589, in spawn_worker
    worker.init_process()
  File "/home/ubuntu/virtualenv/vulndemo/lib/python3.10/site-packages/gunicorn/workers/ggevent.py", line 146, in init_process
    super().init_process()
  File "/home/ubuntu/virtualenv/vulndemo/lib/python3.10/site-packages/gunicorn/workers/base.py", line 134, in init_process
    self.load_wsgi()
  File "/home/ubuntu/virtualenv/vulndemo/lib/python3.10/site-packages/gunicorn/workers/base.py", line 146, in load_wsgi
    self.wsgi = self.app.wsgi()
  File "/home/ubuntu/virtualenv/vulndemo/lib/python3.10/site-packages/gunicorn/app/base.py", line 67, in wsgi
    self.callable = self.load()
  File "/home/ubuntu/virtualenv/vulndemo/lib/python3.10/site-packages/gunicorn/app/wsgiapp.py", line 58, in load
    return self.load_wsgiapp()
  File "/home/ubuntu/virtualenv/vulndemo/lib/python3.10/site-packages/gunicorn/app/wsgiapp.py", line 48, in load_wsgiapp
    return util.import_app(self.app_uri)
  File "/home/ubuntu/virtualenv/vulndemo/lib/python3.10/site-packages/gunicorn/util.py", line 359, in import_app
    mod = importlib.import_module(module)
  File "/usr/lib/python3.10/importlib/__init__.py", line 126, in import_module
    return _bootstrap._gcd_import(name[level:], package, level)
  File "<frozen importlib._bootstrap>", line 1050, in _gcd_import
  File "<frozen importlib._bootstrap>", line 1027, in _find_and_load
  File "<frozen importlib._bootstrap>", line 1006, in _find_and_load_unlocked
  File "<frozen importlib._bootstrap>", line 688, in _load_unlocked
  File "<frozen importlib._bootstrap_external>", line 883, in exec_module
  File "<frozen importlib._bootstrap>", line 241, in _call_with_frames_removed
  File "/home/ubuntu/work/app.py", line 7, in <module>
    from flask_cors import CORS, cross_origin
ModuleNotFoundError: No module named 'flask_cors'
[2022-12-02 15:37:25 +0800] [814916] [ERROR] Exception in worker process
Traceback (most recent call last):
  File "/home/ubuntu/virtualenv/vulndemo/lib/python3.10/site-packages/gunicorn/arbiter.py", line 589, in spawn_worker
    worker.init_process()
  File "/home/ubuntu/virtualenv/vulndemo/lib/python3.10/site-packages/gunicorn/workers/ggevent.py", line 146, in init_process
    super().init_process()
  File "/home/ubuntu/virtualenv/vulndemo/lib/python3.10/site-packages/gunicorn/workers/base.py", line 134, in init_process
    self.load_wsgi()
  File "/home/ubuntu/virtualenv/vulndemo/lib/python3.10/site-packages/gunicorn/workers/base.py", line 146, in load_wsgi
    self.wsgi = self.app.wsgi()
  File "/home/ubuntu/virtualenv/vulndemo/lib/python3.10/site-packages/gunicorn/app/base.py", line 67, in wsgi
    self.callable = self.load()
  File "/home/ubuntu/virtualenv/vulndemo/lib/python3.10/site-packages/gunicorn/app/wsgiapp.py", line 58, in load
    return self.load_wsgiapp()
  File "/home/ubuntu/virtualenv/vulndemo/lib/python3.10/site-packages/gunicorn/app/wsgiapp.py", line 48, in load_wsgiapp
    return util.import_app(self.app_uri)
  File "/home/ubuntu/virtualenv/vulndemo/lib/python3.10/site-packages/gunicorn/util.py", line 359, in import_app
    mod = importlib.import_module(module)
  File "/usr/lib/python3.10/importlib/__init__.py", line 126, in import_module
    return _bootstrap._gcd_import(name[level:], package, level)
  File "<frozen importlib._bootstrap>", line 1050, in _gcd_import
  File "<frozen importlib._bootstrap>", line 1027, in _find_and_load
  File "<frozen importlib._bootstrap>", line 1006, in _find_and_load_unlocked
  File "<frozen importlib._bootstrap>", line 688, in _load_unlocked
  File "<frozen importlib._bootstrap_external>", line 883, in exec_module
  File "<frozen importlib._bootstrap>", line 241, in _call_with_frames_removed
  File "/home/ubuntu/work/app.py", line 7, in <module>
    from flask_cors import CORS, cross_origin
ModuleNotFoundError: No module named 'flask_cors'
[2022-12-02 15:37:25 +0800] [814917] [INFO] Worker exiting (pid: 814917)
[2022-12-02 15:37:25 +0800] [814916] [INFO] Worker exiting (pid: 814916)
Traceback (most recent call last):
  File "src/gevent/greenlet.py", line 908, in gevent._gevent_cgreenlet.Greenlet.run
  File "/home/ubuntu/virtualenv/vulndemo/lib/python3.10/site-packages/gunicorn/arbiter.py", line 242, in handle_chld
    self.reap_workers()
  File "/home/ubuntu/virtualenv/vulndemo/lib/python3.10/site-packages/gunicorn/arbiter.py", line 525, in reap_workers
    raise HaltServer(reason, self.WORKER_BOOT_ERROR)
gunicorn.errors.HaltServer: <HaltServer 'Worker failed to boot.' 3>
2022-12-02T07:37:25Z <Greenlet at 0x7f01e5cb1580: <bound method Arbiter.handle_chld of <gunicorn.arbiter.Arbiter object at 0x7f01e495ada0>>(17, None)> failed with HaltServer

Traceback (most recent call last):
  File "src/gevent/greenlet.py", line 908, in gevent._gevent_cgreenlet.Greenlet.run
  File "/home/ubuntu/virtualenv/vulndemo/lib/python3.10/site-packages/gunicorn/arbiter.py", line 242, in handle_chld
    self.reap_workers()
  File "/home/ubuntu/virtualenv/vulndemo/lib/python3.10/site-packages/gunicorn/arbiter.py", line 525, in reap_workers
    raise HaltServer(reason, self.WORKER_BOOT_ERROR)
gunicorn.errors.HaltServer: <HaltServer 'Worker failed to boot.' 3>
2022-12-02T07:37:25Z <Greenlet at 0x7f01e5cb1580: <bound method Arbiter.handle_chld of <gunicorn.arbiter.Arbiter object at 0x7f01e495ada0>>(17, None)> failed with HaltServer

Traceback (most recent call last):
  File "src/gevent/greenlet.py", line 908, in gevent._gevent_cgreenlet.Greenlet.run
  File "/home/ubuntu/virtualenv/vulndemo/lib/python3.10/site-packages/gunicorn/arbiter.py", line 242, in handle_chld
    self.reap_workers()
  File "/home/ubuntu/virtualenv/vulndemo/lib/python3.10/site-packages/gunicorn/arbiter.py", line 525, in reap_workers
    raise HaltServer(reason, self.WORKER_BOOT_ERROR)
gunicorn.errors.HaltServer: <HaltServer 'Worker failed to boot.' 3>
2022-12-02T07:37:25Z <Greenlet at 0x7f01e5cb1580: <bound method Arbiter.handle_chld of <gunicorn.arbiter.Arbiter object at 0x7f01e495ada0>>(17, None)> failed with HaltServer

[2022-12-02 15:37:54 +0800] [814735] [CRITICAL] WORKER TIMEOUT (pid:814914)
[2022-12-02 15:37:54 +0800] [814735] [CRITICAL] WORKER TIMEOUT (pid:814915)
[2022-12-02 15:37:54 +0800] [814735] [CRITICAL] WORKER TIMEOUT (pid:814916)
[2022-12-02 15:37:54 +0800] [814735] [CRITICAL] WORKER TIMEOUT (pid:814917)
[2022-12-02 15:37:54 +0800] [815003] [INFO] Booting worker with pid: 815003
[2022-12-02 15:37:54 +0800] [815004] [INFO] Booting worker with pid: 815004
[2022-12-02 15:37:55 +0800] [815005] [INFO] Booting worker with pid: 815005
[2022-12-02 15:37:55 +0800] [815006] [INFO] Booting worker with pid: 815006
[2022-12-02 15:37:55 +0800] [815003] [ERROR] Exception in worker process
Traceback (most recent call last):
  File "/home/ubuntu/virtualenv/vulndemo/lib/python3.10/site-packages/gunicorn/arbiter.py", line 589, in spawn_worker
    worker.init_process()
  File "/home/ubuntu/virtualenv/vulndemo/lib/python3.10/site-packages/gunicorn/workers/ggevent.py", line 146, in init_process
    super().init_process()
  File "/home/ubuntu/virtualenv/vulndemo/lib/python3.10/site-packages/gunicorn/workers/base.py", line 134, in init_process
    self.load_wsgi()
  File "/home/ubuntu/virtualenv/vulndemo/lib/python3.10/site-packages/gunicorn/workers/base.py", line 146, in load_wsgi
    self.wsgi = self.app.wsgi()
  File "/home/ubuntu/virtualenv/vulndemo/lib/python3.10/site-packages/gunicorn/app/base.py", line 67, in wsgi
    self.callable = self.load()
  File "/home/ubuntu/virtualenv/vulndemo/lib/python3.10/site-packages/gunicorn/app/wsgiapp.py", line 58, in load
    return self.load_wsgiapp()
  File "/home/ubuntu/virtualenv/vulndemo/lib/python3.10/site-packages/gunicorn/app/wsgiapp.py", line 48, in load_wsgiapp
    return util.import_app(self.app_uri)
  File "/home/ubuntu/virtualenv/vulndemo/lib/python3.10/site-packages/gunicorn/util.py", line 359, in import_app
    mod = importlib.import_module(module)
  File "/usr/lib/python3.10/importlib/__init__.py", line 126, in import_module
    return _bootstrap._gcd_import(name[level:], package, level)
  File "<frozen importlib._bootstrap>", line 1050, in _gcd_import
  File "<frozen importlib._bootstrap>", line 1027, in _find_and_load
  File "<frozen importlib._bootstrap>", line 1006, in _find_and_load_unlocked
  File "<frozen importlib._bootstrap>", line 688, in _load_unlocked
  File "<frozen importlib._bootstrap_external>", line 883, in exec_module
  File "<frozen importlib._bootstrap>", line 241, in _call_with_frames_removed
  File "/home/ubuntu/work/app.py", line 7, in <module>
    from flask_cors import CORS, cross_origin
ModuleNotFoundError: No module named 'flask_cors'
[2022-12-02 15:37:55 +0800] [815003] [INFO] Worker exiting (pid: 815003)
[2022-12-02 15:37:55 +0800] [815004] [ERROR] Exception in worker process
Traceback (most recent call last):
  File "/home/ubuntu/virtualenv/vulndemo/lib/python3.10/site-packages/gunicorn/arbiter.py", line 589, in spawn_worker
    worker.init_process()
  File "/home/ubuntu/virtualenv/vulndemo/lib/python3.10/site-packages/gunicorn/workers/ggevent.py", line 146, in init_process
    super().init_process()
  File "/home/ubuntu/virtualenv/vulndemo/lib/python3.10/site-packages/gunicorn/workers/base.py", line 134, in init_process
    self.load_wsgi()
  File "/home/ubuntu/virtualenv/vulndemo/lib/python3.10/site-packages/gunicorn/workers/base.py", line 146, in load_wsgi
    self.wsgi = self.app.wsgi()
  File "/home/ubuntu/virtualenv/vulndemo/lib/python3.10/site-packages/gunicorn/app/base.py", line 67, in wsgi
    self.callable = self.load()
  File "/home/ubuntu/virtualenv/vulndemo/lib/python3.10/site-packages/gunicorn/app/wsgiapp.py", line 58, in load
    return self.load_wsgiapp()
  File "/home/ubuntu/virtualenv/vulndemo/lib/python3.10/site-packages/gunicorn/app/wsgiapp.py", line 48, in load_wsgiapp
    return util.import_app(self.app_uri)
  File "/home/ubuntu/virtualenv/vulndemo/lib/python3.10/site-packages/gunicorn/util.py", line 359, in import_app
    mod = importlib.import_module(module)
  File "/usr/lib/python3.10/importlib/__init__.py", line 126, in import_module
    return _bootstrap._gcd_import(name[level:], package, level)
  File "<frozen importlib._bootstrap>", line 1050, in _gcd_import
  File "<frozen importlib._bootstrap>", line 1027, in _find_and_load
  File "<frozen importlib._bootstrap>", line 1006, in _find_and_load_unlocked
  File "<frozen importlib._bootstrap>", line 688, in _load_unlocked
  File "<frozen importlib._bootstrap_external>", line 883, in exec_module
  File "<frozen importlib._bootstrap>", line 241, in _call_with_frames_removed
  File "/home/ubuntu/work/app.py", line 7, in <module>
    from flask_cors import CORS, cross_origin
ModuleNotFoundError: No module named 'flask_cors'
[2022-12-02 15:37:55 +0800] [815004] [INFO] Worker exiting (pid: 815004)
[2022-12-02 15:37:55 +0800] [815005] [ERROR] Exception in worker process
Traceback (most recent call last):
  File "/home/ubuntu/virtualenv/vulndemo/lib/python3.10/site-packages/gunicorn/arbiter.py", line 589, in spawn_worker
    worker.init_process()
  File "/home/ubuntu/virtualenv/vulndemo/lib/python3.10/site-packages/gunicorn/workers/ggevent.py", line 146, in init_process
    super().init_process()
  File "/home/ubuntu/virtualenv/vulndemo/lib/python3.10/site-packages/gunicorn/workers/base.py", line 134, in init_process
    self.load_wsgi()
  File "/home/ubuntu/virtualenv/vulndemo/lib/python3.10/site-packages/gunicorn/workers/base.py", line 146, in load_wsgi
    self.wsgi = self.app.wsgi()
  File "/home/ubuntu/virtualenv/vulndemo/lib/python3.10/site-packages/gunicorn/app/base.py", line 67, in wsgi
    self.callable = self.load()
  File "/home/ubuntu/virtualenv/vulndemo/lib/python3.10/site-packages/gunicorn/app/wsgiapp.py", line 58, in load
    return self.load_wsgiapp()
  File "/home/ubuntu/virtualenv/vulndemo/lib/python3.10/site-packages/gunicorn/app/wsgiapp.py", line 48, in load_wsgiapp
    return util.import_app(self.app_uri)
  File "/home/ubuntu/virtualenv/vulndemo/lib/python3.10/site-packages/gunicorn/util.py", line 359, in import_app
    mod = importlib.import_module(module)
  File "/usr/lib/python3.10/importlib/__init__.py", line 126, in import_module
    return _bootstrap._gcd_import(name[level:], package, level)
  File "<frozen importlib._bootstrap>", line 1050, in _gcd_import
  File "<frozen importlib._bootstrap>", line 1027, in _find_and_load
  File "<frozen importlib._bootstrap>", line 1006, in _find_and_load_unlocked
  File "<frozen importlib._bootstrap>", line 688, in _load_unlocked
  File "<frozen importlib._bootstrap_external>", line 883, in exec_module
  File "<frozen importlib._bootstrap>", line 241, in _call_with_frames_removed
  File "/home/ubuntu/work/app.py", line 7, in <module>
    from flask_cors import CORS, cross_origin
ModuleNotFoundError: No module named 'flask_cors'
[2022-12-02 15:37:55 +0800] [815005] [INFO] Worker exiting (pid: 815005)
Traceback (most recent call last):
  File "src/gevent/greenlet.py", line 908, in gevent._gevent_cgreenlet.Greenlet.run
  File "/home/ubuntu/virtualenv/vulndemo/lib/python3.10/site-packages/gunicorn/arbiter.py", line 242, in handle_chld
    self.reap_workers()
  File "/home/ubuntu/virtualenv/vulndemo/lib/python3.10/site-packages/gunicorn/arbiter.py", line 525, in reap_workers
    raise HaltServer(reason, self.WORKER_BOOT_ERROR)
gunicorn.errors.HaltServer: <HaltServer 'Worker failed to boot.' 3>
2022-12-02T07:37:55Z <Greenlet at 0x7f01e5cb1580: <bound method Arbiter.handle_chld of <gunicorn.arbiter.Arbiter object at 0x7f01e495ada0>>(17, None)> failed with HaltServer

Traceback (most recent call last):
  File "src/gevent/greenlet.py", line 908, in gevent._gevent_cgreenlet.Greenlet.run
  File "/home/ubuntu/virtualenv/vulndemo/lib/python3.10/site-packages/gunicorn/arbiter.py", line 242, in handle_chld
    self.reap_workers()
  File "/home/ubuntu/virtualenv/vulndemo/lib/python3.10/site-packages/gunicorn/arbiter.py", line 525, in reap_workers
    raise HaltServer(reason, self.WORKER_BOOT_ERROR)
gunicorn.errors.HaltServer: <HaltServer 'Worker failed to boot.' 3>
2022-12-02T07:37:55Z <Greenlet at 0x7f01e5cb1580: <bound method Arbiter.handle_chld of <gunicorn.arbiter.Arbiter object at 0x7f01e495ada0>>(17, None)> failed with HaltServer

Traceback (most recent call last):
  File "src/gevent/greenlet.py", line 908, in gevent._gevent_cgreenlet.Greenlet.run
  File "/home/ubuntu/virtualenv/vulndemo/lib/python3.10/site-packages/gunicorn/arbiter.py", line 242, in handle_chld
    self.reap_workers()
  File "/home/ubuntu/virtualenv/vulndemo/lib/python3.10/site-packages/gunicorn/arbiter.py", line 525, in reap_workers
    raise HaltServer(reason, self.WORKER_BOOT_ERROR)
gunicorn.errors.HaltServer: <HaltServer 'Worker failed to boot.' 3>
2022-12-02T07:37:55Z <Greenlet at 0x7f01e5cb1580: <bound method Arbiter.handle_chld of <gunicorn.arbiter.Arbiter object at 0x7f01e495ada0>>(17, None)> failed with HaltServer

[2022-12-02 15:37:55 +0800] [815006] [ERROR] Exception in worker process
Traceback (most recent call last):
  File "/home/ubuntu/virtualenv/vulndemo/lib/python3.10/site-packages/gunicorn/arbiter.py", line 589, in spawn_worker
    worker.init_process()
  File "/home/ubuntu/virtualenv/vulndemo/lib/python3.10/site-packages/gunicorn/workers/ggevent.py", line 146, in init_process
    super().init_process()
  File "/home/ubuntu/virtualenv/vulndemo/lib/python3.10/site-packages/gunicorn/workers/base.py", line 134, in init_process
    self.load_wsgi()
  File "/home/ubuntu/virtualenv/vulndemo/lib/python3.10/site-packages/gunicorn/workers/base.py", line 146, in load_wsgi
    self.wsgi = self.app.wsgi()
  File "/home/ubuntu/virtualenv/vulndemo/lib/python3.10/site-packages/gunicorn/app/base.py", line 67, in wsgi
    self.callable = self.load()
  File "/home/ubuntu/virtualenv/vulndemo/lib/python3.10/site-packages/gunicorn/app/wsgiapp.py", line 58, in load
    return self.load_wsgiapp()
  File "/home/ubuntu/virtualenv/vulndemo/lib/python3.10/site-packages/gunicorn/app/wsgiapp.py", line 48, in load_wsgiapp
    return util.import_app(self.app_uri)
  File "/home/ubuntu/virtualenv/vulndemo/lib/python3.10/site-packages/gunicorn/util.py", line 359, in import_app
    mod = importlib.import_module(module)
  File "/usr/lib/python3.10/importlib/__init__.py", line 126, in import_module
    return _bootstrap._gcd_import(name[level:], package, level)
  File "<frozen importlib._bootstrap>", line 1050, in _gcd_import
  File "<frozen importlib._bootstrap>", line 1027, in _find_and_load
  File "<frozen importlib._bootstrap>", line 1006, in _find_and_load_unlocked
  File "<frozen importlib._bootstrap>", line 688, in _load_unlocked
  File "<frozen importlib._bootstrap_external>", line 883, in exec_module
  File "<frozen importlib._bootstrap>", line 241, in _call_with_frames_removed
  File "/home/ubuntu/work/app.py", line 7, in <module>
    from flask_cors import CORS, cross_origin
ModuleNotFoundError: No module named 'flask_cors'
[2022-12-02 15:37:55 +0800] [815006] [INFO] Worker exiting (pid: 815006)
Traceback (most recent call last):
  File "src/gevent/greenlet.py", line 908, in gevent._gevent_cgreenlet.Greenlet.run
  File "/home/ubuntu/virtualenv/vulndemo/lib/python3.10/site-packages/gunicorn/arbiter.py", line 242, in handle_chld
    self.reap_workers()
  File "/home/ubuntu/virtualenv/vulndemo/lib/python3.10/site-packages/gunicorn/arbiter.py", line 525, in reap_workers
    raise HaltServer(reason, self.WORKER_BOOT_ERROR)
gunicorn.errors.HaltServer: <HaltServer 'Worker failed to boot.' 3>
2022-12-02T07:37:55Z <Greenlet at 0x7f01e5cb1580: <bound method Arbiter.handle_chld of <gunicorn.arbiter.Arbiter object at 0x7f01e495ada0>>(17, None)> failed with HaltServer

[2022-12-02 15:38:03 +0800] [814735] [INFO] Handling signal: term
[2022-12-02 15:38:03 +0800] [814735] [INFO] Shutting down: Master
[2022-12-02 15:38:04 +0800] [815053] [DEBUG] Current configuration:
  config: /home/ubuntu/work/gconfig.py
  wsgi_app: None
  bind: ['0.0.0.0:5000']
  backlog: 2048
  workers: 4
  worker_class: gevent
  threads: 1
  worker_connections: 1000
  max_requests: 0
  max_requests_jitter: 0
  timeout: 30
  graceful_timeout: 30
  keepalive: 2
  limit_request_line: 4094
  limit_request_fields: 100
  limit_request_field_size: 8190
  reload: False
  reload_engine: auto
  reload_extra_files: []
  spew: False
  check_config: False
  print_config: False
  preload_app: False
  sendfile: None
  reuse_port: False
  chdir: /home/ubuntu/work
  daemon: False
  raw_env: []
  pidfile: log/gunicorn.pid
  worker_tmp_dir: None
  user: 0
  group: 0
  umask: 0
  initgroups: False
  tmp_upload_dir: None
  secure_scheme_headers: {'X-FORWARDED-PROTOCOL': 'ssl', 'X-FORWARDED-PROTO': 'https', 'X-FORWARDED-SSL': 'on'}
  forwarded_allow_ips: ['127.0.0.1']
  accesslog: None
  disable_redirect_access_to_syslog: False
  access_log_format: %(h)s %(l)s %(u)s %(t)s "%(r)s" %(s)s %(b)s "%(f)s" "%(a)s"
  errorlog: -
  loglevel: debug
  capture_output: False
  logger_class: gunicorn.glogging.Logger
  logconfig: None
  logconfig_dict: {}
  syslog_addr: udp://localhost:514
  syslog: False
  syslog_prefix: None
  syslog_facility: user
  enable_stdio_inheritance: False
  statsd_host: None
  dogstatsd_tags: 
  statsd_prefix: 
  proc_name: None
  default_proc_name: app:app
  pythonpath: None
  paste: None
  on_starting: <function OnStarting.on_starting at 0x7f2b9166e4d0>
  on_reload: <function OnReload.on_reload at 0x7f2b9166e5f0>
  when_ready: <function WhenReady.when_ready at 0x7f2b9166e710>
  pre_fork: <function Prefork.pre_fork at 0x7f2b9166e830>
  post_fork: <function Postfork.post_fork at 0x7f2b9166e950>
  post_worker_init: <function PostWorkerInit.post_worker_init at 0x7f2b9166ea70>
  worker_int: <function WorkerInt.worker_int at 0x7f2b9166eb90>
  worker_abort: <function WorkerAbort.worker_abort at 0x7f2b9166ecb0>
  pre_exec: <function PreExec.pre_exec at 0x7f2b9166edd0>
  pre_request: <function PreRequest.pre_request at 0x7f2b9166eef0>
  post_request: <function PostRequest.post_request at 0x7f2b9166ef80>
  child_exit: <function ChildExit.child_exit at 0x7f2b9166f0a0>
  worker_exit: <function WorkerExit.worker_exit at 0x7f2b9166f1c0>
  nworkers_changed: <function NumWorkersChanged.nworkers_changed at 0x7f2b9166f2e0>
  on_exit: <function OnExit.on_exit at 0x7f2b9166f400>
  proxy_protocol: False
  proxy_allow_ips: ['127.0.0.1']
  keyfile: None
  certfile: None
  ssl_version: 2
  cert_reqs: 0
  ca_certs: None
  suppress_ragged_eofs: True
  do_handshake_on_connect: False
  ciphers: None
  raw_paste_global_conf: []
  strip_header_spaces: False
[2022-12-02 15:38:04 +0800] [815053] [INFO] Starting gunicorn 20.1.0
[2022-12-02 15:38:04 +0800] [815053] [DEBUG] Arbiter booted
[2022-12-02 15:38:04 +0800] [815053] [INFO] Listening at: http://0.0.0.0:5000 (815053)
[2022-12-02 15:38:04 +0800] [815053] [INFO] Using worker: gevent
[2022-12-02 15:38:04 +0800] [815054] [INFO] Booting worker with pid: 815054
[2022-12-02 15:38:04 +0800] [815055] [INFO] Booting worker with pid: 815055
[2022-12-02 15:38:04 +0800] [815056] [INFO] Booting worker with pid: 815056
[2022-12-02 15:38:04 +0800] [815057] [INFO] Booting worker with pid: 815057
[2022-12-02 15:38:04 +0800] [815053] [DEBUG] 4 workers
[2022-12-02 15:38:05 +0800] [815054] [ERROR] Exception in worker process
Traceback (most recent call last):
  File "/home/ubuntu/virtualenv/vulndemo/lib/python3.10/site-packages/gunicorn/arbiter.py", line 589, in spawn_worker
    worker.init_process()
  File "/home/ubuntu/virtualenv/vulndemo/lib/python3.10/site-packages/gunicorn/workers/ggevent.py", line 146, in init_process
    super().init_process()
  File "/home/ubuntu/virtualenv/vulndemo/lib/python3.10/site-packages/gunicorn/workers/base.py", line 134, in init_process
    self.load_wsgi()
  File "/home/ubuntu/virtualenv/vulndemo/lib/python3.10/site-packages/gunicorn/workers/base.py", line 146, in load_wsgi
    self.wsgi = self.app.wsgi()
  File "/home/ubuntu/virtualenv/vulndemo/lib/python3.10/site-packages/gunicorn/app/base.py", line 67, in wsgi
    self.callable = self.load()
  File "/home/ubuntu/virtualenv/vulndemo/lib/python3.10/site-packages/gunicorn/app/wsgiapp.py", line 58, in load
    return self.load_wsgiapp()
  File "/home/ubuntu/virtualenv/vulndemo/lib/python3.10/site-packages/gunicorn/app/wsgiapp.py", line 48, in load_wsgiapp
    return util.import_app(self.app_uri)
  File "/home/ubuntu/virtualenv/vulndemo/lib/python3.10/site-packages/gunicorn/util.py", line 359, in import_app
    mod = importlib.import_module(module)
  File "/usr/lib/python3.10/importlib/__init__.py", line 126, in import_module
    return _bootstrap._gcd_import(name[level:], package, level)
  File "<frozen importlib._bootstrap>", line 1050, in _gcd_import
  File "<frozen importlib._bootstrap>", line 1027, in _find_and_load
  File "<frozen importlib._bootstrap>", line 1006, in _find_and_load_unlocked
  File "<frozen importlib._bootstrap>", line 688, in _load_unlocked
  File "<frozen importlib._bootstrap_external>", line 883, in exec_module
  File "<frozen importlib._bootstrap>", line 241, in _call_with_frames_removed
  File "/home/ubuntu/work/app.py", line 7, in <module>
    from flask_cors import CORS, cross_origin
ModuleNotFoundError: No module named 'flask_cors'
[2022-12-02 15:38:05 +0800] [815054] [INFO] Worker exiting (pid: 815054)
[2022-12-02 15:38:05 +0800] [815055] [ERROR] Exception in worker process
Traceback (most recent call last):
  File "/home/ubuntu/virtualenv/vulndemo/lib/python3.10/site-packages/gunicorn/arbiter.py", line 589, in spawn_worker
    worker.init_process()
  File "/home/ubuntu/virtualenv/vulndemo/lib/python3.10/site-packages/gunicorn/workers/ggevent.py", line 146, in init_process
    super().init_process()
  File "/home/ubuntu/virtualenv/vulndemo/lib/python3.10/site-packages/gunicorn/workers/base.py", line 134, in init_process
    self.load_wsgi()
  File "/home/ubuntu/virtualenv/vulndemo/lib/python3.10/site-packages/gunicorn/workers/base.py", line 146, in load_wsgi
    self.wsgi = self.app.wsgi()
  File "/home/ubuntu/virtualenv/vulndemo/lib/python3.10/site-packages/gunicorn/app/base.py", line 67, in wsgi
    self.callable = self.load()
  File "/home/ubuntu/virtualenv/vulndemo/lib/python3.10/site-packages/gunicorn/app/wsgiapp.py", line 58, in load
    return self.load_wsgiapp()
  File "/home/ubuntu/virtualenv/vulndemo/lib/python3.10/site-packages/gunicorn/app/wsgiapp.py", line 48, in load_wsgiapp
    return util.import_app(self.app_uri)
  File "/home/ubuntu/virtualenv/vulndemo/lib/python3.10/site-packages/gunicorn/util.py", line 359, in import_app
    mod = importlib.import_module(module)
  File "/usr/lib/python3.10/importlib/__init__.py", line 126, in import_module
    return _bootstrap._gcd_import(name[level:], package, level)
  File "<frozen importlib._bootstrap>", line 1050, in _gcd_import
  File "<frozen importlib._bootstrap>", line 1027, in _find_and_load
  File "<frozen importlib._bootstrap>", line 1006, in _find_and_load_unlocked
  File "<frozen importlib._bootstrap>", line 688, in _load_unlocked
  File "<frozen importlib._bootstrap_external>", line 883, in exec_module
  File "<frozen importlib._bootstrap>", line 241, in _call_with_frames_removed
  File "/home/ubuntu/work/app.py", line 7, in <module>
    from flask_cors import CORS, cross_origin
ModuleNotFoundError: No module named 'flask_cors'
[2022-12-02 15:38:05 +0800] [815055] [INFO] Worker exiting (pid: 815055)
Traceback (most recent call last):
  File "src/gevent/greenlet.py", line 908, in gevent._gevent_cgreenlet.Greenlet.run
  File "/home/ubuntu/virtualenv/vulndemo/lib/python3.10/site-packages/gunicorn/arbiter.py", line 242, in handle_chld
    self.reap_workers()
  File "/home/ubuntu/virtualenv/vulndemo/lib/python3.10/site-packages/gunicorn/arbiter.py", line 525, in reap_workers
    raise HaltServer(reason, self.WORKER_BOOT_ERROR)
gunicorn.errors.HaltServer: <HaltServer 'Worker failed to boot.' 3>
2022-12-02T07:38:05Z <Greenlet at 0x7f2b90eba700: <bound method Arbiter.handle_chld of <gunicorn.arbiter.Arbiter object at 0x7f2b90e99f00>>(17, None)> failed with HaltServer

[2022-12-02 15:38:05 +0800] [815056] [ERROR] Exception in worker process
Traceback (most recent call last):
  File "/home/ubuntu/virtualenv/vulndemo/lib/python3.10/site-packages/gunicorn/arbiter.py", line 589, in spawn_worker
    worker.init_process()
  File "/home/ubuntu/virtualenv/vulndemo/lib/python3.10/site-packages/gunicorn/workers/ggevent.py", line 146, in init_process
    super().init_process()
  File "/home/ubuntu/virtualenv/vulndemo/lib/python3.10/site-packages/gunicorn/workers/base.py", line 134, in init_process
    self.load_wsgi()
  File "/home/ubuntu/virtualenv/vulndemo/lib/python3.10/site-packages/gunicorn/workers/base.py", line 146, in load_wsgi
    self.wsgi = self.app.wsgi()
  File "/home/ubuntu/virtualenv/vulndemo/lib/python3.10/site-packages/gunicorn/app/base.py", line 67, in wsgi
    self.callable = self.load()
  File "/home/ubuntu/virtualenv/vulndemo/lib/python3.10/site-packages/gunicorn/app/wsgiapp.py", line 58, in load
    return self.load_wsgiapp()
  File "/home/ubuntu/virtualenv/vulndemo/lib/python3.10/site-packages/gunicorn/app/wsgiapp.py", line 48, in load_wsgiapp
    return util.import_app(self.app_uri)
  File "/home/ubuntu/virtualenv/vulndemo/lib/python3.10/site-packages/gunicorn/util.py", line 359, in import_app
    mod = importlib.import_module(module)
  File "/usr/lib/python3.10/importlib/__init__.py", line 126, in import_module
    return _bootstrap._gcd_import(name[level:], package, level)
  File "<frozen importlib._bootstrap>", line 1050, in _gcd_import
  File "<frozen importlib._bootstrap>", line 1027, in _find_and_load
  File "<frozen importlib._bootstrap>", line 1006, in _find_and_load_unlocked
  File "<frozen importlib._bootstrap>", line 688, in _load_unlocked
  File "<frozen importlib._bootstrap_external>", line 883, in exec_module
  File "<frozen importlib._bootstrap>", line 241, in _call_with_frames_removed
  File "/home/ubuntu/work/app.py", line 7, in <module>
    from flask_cors import CORS, cross_origin
ModuleNotFoundError: No module named 'flask_cors'
[2022-12-02 15:38:05 +0800] [815056] [INFO] Worker exiting (pid: 815056)
Traceback (most recent call last):
  File "src/gevent/greenlet.py", line 908, in gevent._gevent_cgreenlet.Greenlet.run
  File "/home/ubuntu/virtualenv/vulndemo/lib/python3.10/site-packages/gunicorn/arbiter.py", line 242, in handle_chld
    self.reap_workers()
  File "/home/ubuntu/virtualenv/vulndemo/lib/python3.10/site-packages/gunicorn/arbiter.py", line 525, in reap_workers
    raise HaltServer(reason, self.WORKER_BOOT_ERROR)
gunicorn.errors.HaltServer: <HaltServer 'Worker failed to boot.' 3>
2022-12-02T07:38:05Z <Greenlet at 0x7f2b90eba700: <bound method Arbiter.handle_chld of <gunicorn.arbiter.Arbiter object at 0x7f2b90e99f00>>(17, None)> failed with HaltServer

Traceback (most recent call last):
  File "src/gevent/greenlet.py", line 908, in gevent._gevent_cgreenlet.Greenlet.run
  File "/home/ubuntu/virtualenv/vulndemo/lib/python3.10/site-packages/gunicorn/arbiter.py", line 242, in handle_chld
    self.reap_workers()
  File "/home/ubuntu/virtualenv/vulndemo/lib/python3.10/site-packages/gunicorn/arbiter.py", line 525, in reap_workers
    raise HaltServer(reason, self.WORKER_BOOT_ERROR)
gunicorn.errors.HaltServer: <HaltServer 'Worker failed to boot.' 3>
2022-12-02T07:38:05Z <Greenlet at 0x7f2b90eba700: <bound method Arbiter.handle_chld of <gunicorn.arbiter.Arbiter object at 0x7f2b90e99f00>>(17, None)> failed with HaltServer

[2022-12-02 15:38:05 +0800] [815057] [ERROR] Exception in worker process
Traceback (most recent call last):
  File "/home/ubuntu/virtualenv/vulndemo/lib/python3.10/site-packages/gunicorn/arbiter.py", line 589, in spawn_worker
    worker.init_process()
  File "/home/ubuntu/virtualenv/vulndemo/lib/python3.10/site-packages/gunicorn/workers/ggevent.py", line 146, in init_process
    super().init_process()
  File "/home/ubuntu/virtualenv/vulndemo/lib/python3.10/site-packages/gunicorn/workers/base.py", line 134, in init_process
    self.load_wsgi()
  File "/home/ubuntu/virtualenv/vulndemo/lib/python3.10/site-packages/gunicorn/workers/base.py", line 146, in load_wsgi
    self.wsgi = self.app.wsgi()
  File "/home/ubuntu/virtualenv/vulndemo/lib/python3.10/site-packages/gunicorn/app/base.py", line 67, in wsgi
    self.callable = self.load()
  File "/home/ubuntu/virtualenv/vulndemo/lib/python3.10/site-packages/gunicorn/app/wsgiapp.py", line 58, in load
    return self.load_wsgiapp()
  File "/home/ubuntu/virtualenv/vulndemo/lib/python3.10/site-packages/gunicorn/app/wsgiapp.py", line 48, in load_wsgiapp
    return util.import_app(self.app_uri)
  File "/home/ubuntu/virtualenv/vulndemo/lib/python3.10/site-packages/gunicorn/util.py", line 359, in import_app
    mod = importlib.import_module(module)
  File "/usr/lib/python3.10/importlib/__init__.py", line 126, in import_module
    return _bootstrap._gcd_import(name[level:], package, level)
  File "<frozen importlib._bootstrap>", line 1050, in _gcd_import
  File "<frozen importlib._bootstrap>", line 1027, in _find_and_load
  File "<frozen importlib._bootstrap>", line 1006, in _find_and_load_unlocked
  File "<frozen importlib._bootstrap>", line 688, in _load_unlocked
  File "<frozen importlib._bootstrap_external>", line 883, in exec_module
  File "<frozen importlib._bootstrap>", line 241, in _call_with_frames_removed
  File "/home/ubuntu/work/app.py", line 7, in <module>
    from flask_cors import CORS, cross_origin
ModuleNotFoundError: No module named 'flask_cors'
[2022-12-02 15:38:05 +0800] [815057] [INFO] Worker exiting (pid: 815057)
Traceback (most recent call last):
  File "src/gevent/greenlet.py", line 908, in gevent._gevent_cgreenlet.Greenlet.run
  File "/home/ubuntu/virtualenv/vulndemo/lib/python3.10/site-packages/gunicorn/arbiter.py", line 242, in handle_chld
    self.reap_workers()
  File "/home/ubuntu/virtualenv/vulndemo/lib/python3.10/site-packages/gunicorn/arbiter.py", line 525, in reap_workers
    raise HaltServer(reason, self.WORKER_BOOT_ERROR)
gunicorn.errors.HaltServer: <HaltServer 'Worker failed to boot.' 3>
2022-12-02T07:38:05Z <Greenlet at 0x7f2b90eba700: <bound method Arbiter.handle_chld of <gunicorn.arbiter.Arbiter object at 0x7f2b90e99f00>>(17, None)> failed with HaltServer

[2022-12-02 15:38:35 +0800] [815053] [CRITICAL] WORKER TIMEOUT (pid:815054)
[2022-12-02 15:38:35 +0800] [815053] [CRITICAL] WORKER TIMEOUT (pid:815055)
[2022-12-02 15:38:35 +0800] [815053] [CRITICAL] WORKER TIMEOUT (pid:815056)
[2022-12-02 15:38:35 +0800] [815053] [CRITICAL] WORKER TIMEOUT (pid:815057)
[2022-12-02 15:38:35 +0800] [815134] [INFO] Booting worker with pid: 815134
[2022-12-02 15:38:35 +0800] [815135] [INFO] Booting worker with pid: 815135
[2022-12-02 15:38:35 +0800] [815136] [INFO] Booting worker with pid: 815136
[2022-12-02 15:38:35 +0800] [815137] [INFO] Booting worker with pid: 815137
[2022-12-02 15:38:35 +0800] [815134] [ERROR] Exception in worker process
Traceback (most recent call last):
  File "/home/ubuntu/virtualenv/vulndemo/lib/python3.10/site-packages/gunicorn/arbiter.py", line 589, in spawn_worker
    worker.init_process()
  File "/home/ubuntu/virtualenv/vulndemo/lib/python3.10/site-packages/gunicorn/workers/ggevent.py", line 146, in init_process
    super().init_process()
  File "/home/ubuntu/virtualenv/vulndemo/lib/python3.10/site-packages/gunicorn/workers/base.py", line 134, in init_process
    self.load_wsgi()
  File "/home/ubuntu/virtualenv/vulndemo/lib/python3.10/site-packages/gunicorn/workers/base.py", line 146, in load_wsgi
    self.wsgi = self.app.wsgi()
  File "/home/ubuntu/virtualenv/vulndemo/lib/python3.10/site-packages/gunicorn/app/base.py", line 67, in wsgi
    self.callable = self.load()
  File "/home/ubuntu/virtualenv/vulndemo/lib/python3.10/site-packages/gunicorn/app/wsgiapp.py", line 58, in load
    return self.load_wsgiapp()
  File "/home/ubuntu/virtualenv/vulndemo/lib/python3.10/site-packages/gunicorn/app/wsgiapp.py", line 48, in load_wsgiapp
    return util.import_app(self.app_uri)
  File "/home/ubuntu/virtualenv/vulndemo/lib/python3.10/site-packages/gunicorn/util.py", line 359, in import_app
    mod = importlib.import_module(module)
  File "/usr/lib/python3.10/importlib/__init__.py", line 126, in import_module
    return _bootstrap._gcd_import(name[level:], package, level)
  File "<frozen importlib._bootstrap>", line 1050, in _gcd_import
  File "<frozen importlib._bootstrap>", line 1027, in _find_and_load
  File "<frozen importlib._bootstrap>", line 1006, in _find_and_load_unlocked
  File "<frozen importlib._bootstrap>", line 688, in _load_unlocked
  File "<frozen importlib._bootstrap_external>", line 883, in exec_module
  File "<frozen importlib._bootstrap>", line 241, in _call_with_frames_removed
  File "/home/ubuntu/work/app.py", line 7, in <module>
    from flask_cors import CORS, cross_origin
ModuleNotFoundError: No module named 'flask_cors'
[2022-12-02 15:38:35 +0800] [815134] [INFO] Worker exiting (pid: 815134)
Traceback (most recent call last):
  File "src/gevent/greenlet.py", line 908, in gevent._gevent_cgreenlet.Greenlet.run
  File "/home/ubuntu/virtualenv/vulndemo/lib/python3.10/site-packages/gunicorn/arbiter.py", line 242, in handle_chld
    self.reap_workers()
  File "/home/ubuntu/virtualenv/vulndemo/lib/python3.10/site-packages/gunicorn/arbiter.py", line 525, in reap_workers
    raise HaltServer(reason, self.WORKER_BOOT_ERROR)
gunicorn.errors.HaltServer: <HaltServer 'Worker failed to boot.' 3>
2022-12-02T07:38:35Z <Greenlet at 0x7f2b90eba700: <bound method Arbiter.handle_chld of <gunicorn.arbiter.Arbiter object at 0x7f2b90e99f00>>(17, None)> failed with HaltServer

[2022-12-02 15:38:35 +0800] [815137] [ERROR] Exception in worker process
Traceback (most recent call last):
  File "/home/ubuntu/virtualenv/vulndemo/lib/python3.10/site-packages/gunicorn/arbiter.py", line 589, in spawn_worker
    worker.init_process()
  File "/home/ubuntu/virtualenv/vulndemo/lib/python3.10/site-packages/gunicorn/workers/ggevent.py", line 146, in init_process
    super().init_process()
  File "/home/ubuntu/virtualenv/vulndemo/lib/python3.10/site-packages/gunicorn/workers/base.py", line 134, in init_process
    self.load_wsgi()
  File "/home/ubuntu/virtualenv/vulndemo/lib/python3.10/site-packages/gunicorn/workers/base.py", line 146, in load_wsgi
    self.wsgi = self.app.wsgi()
  File "/home/ubuntu/virtualenv/vulndemo/lib/python3.10/site-packages/gunicorn/app/base.py", line 67, in wsgi
    self.callable = self.load()
  File "/home/ubuntu/virtualenv/vulndemo/lib/python3.10/site-packages/gunicorn/app/wsgiapp.py", line 58, in load
    return self.load_wsgiapp()
  File "/home/ubuntu/virtualenv/vulndemo/lib/python3.10/site-packages/gunicorn/app/wsgiapp.py", line 48, in load_wsgiapp
    return util.import_app(self.app_uri)
  File "/home/ubuntu/virtualenv/vulndemo/lib/python3.10/site-packages/gunicorn/util.py", line 359, in import_app
    mod = importlib.import_module(module)
  File "/usr/lib/python3.10/importlib/__init__.py", line 126, in import_module
    return _bootstrap._gcd_import(name[level:], package, level)
  File "<frozen importlib._bootstrap>", line 1050, in _gcd_import
  File "<frozen importlib._bootstrap>", line 1027, in _find_and_load
  File "<frozen importlib._bootstrap>", line 1006, in _find_and_load_unlocked
  File "<frozen importlib._bootstrap>", line 688, in _load_unlocked
  File "<frozen importlib._bootstrap_external>", line 883, in exec_module
  File "<frozen importlib._bootstrap>", line 241, in _call_with_frames_removed
  File "/home/ubuntu/work/app.py", line 7, in <module>
    from flask_cors import CORS, cross_origin
ModuleNotFoundError: No module named 'flask_cors'
[2022-12-02 15:38:35 +0800] [815137] [INFO] Worker exiting (pid: 815137)
[2022-12-02 15:38:35 +0800] [815135] [ERROR] Exception in worker process
Traceback (most recent call last):
  File "/home/ubuntu/virtualenv/vulndemo/lib/python3.10/site-packages/gunicorn/arbiter.py", line 589, in spawn_worker
    worker.init_process()
  File "/home/ubuntu/virtualenv/vulndemo/lib/python3.10/site-packages/gunicorn/workers/ggevent.py", line 146, in init_process
    super().init_process()
  File "/home/ubuntu/virtualenv/vulndemo/lib/python3.10/site-packages/gunicorn/workers/base.py", line 134, in init_process
    self.load_wsgi()
  File "/home/ubuntu/virtualenv/vulndemo/lib/python3.10/site-packages/gunicorn/workers/base.py", line 146, in load_wsgi
    self.wsgi = self.app.wsgi()
  File "/home/ubuntu/virtualenv/vulndemo/lib/python3.10/site-packages/gunicorn/app/base.py", line 67, in wsgi
    self.callable = self.load()
  File "/home/ubuntu/virtualenv/vulndemo/lib/python3.10/site-packages/gunicorn/app/wsgiapp.py", line 58, in load
    return self.load_wsgiapp()
  File "/home/ubuntu/virtualenv/vulndemo/lib/python3.10/site-packages/gunicorn/app/wsgiapp.py", line 48, in load_wsgiapp
    return util.import_app(self.app_uri)
  File "/home/ubuntu/virtualenv/vulndemo/lib/python3.10/site-packages/gunicorn/util.py", line 359, in import_app
    mod = importlib.import_module(module)
  File "/usr/lib/python3.10/importlib/__init__.py", line 126, in import_module
    return _bootstrap._gcd_import(name[level:], package, level)
  File "<frozen importlib._bootstrap>", line 1050, in _gcd_import
  File "<frozen importlib._bootstrap>", line 1027, in _find_and_load
  File "<frozen importlib._bootstrap>", line 1006, in _find_and_load_unlocked
  File "<frozen importlib._bootstrap>", line 688, in _load_unlocked
  File "<frozen importlib._bootstrap_external>", line 883, in exec_module
  File "<frozen importlib._bootstrap>", line 241, in _call_with_frames_removed
  File "/home/ubuntu/work/app.py", line 7, in <module>
    from flask_cors import CORS, cross_origin
ModuleNotFoundError: No module named 'flask_cors'
[2022-12-02 15:38:35 +0800] [815135] [INFO] Worker exiting (pid: 815135)
[2022-12-02 15:38:35 +0800] [815136] [ERROR] Exception in worker process
Traceback (most recent call last):
  File "/home/ubuntu/virtualenv/vulndemo/lib/python3.10/site-packages/gunicorn/arbiter.py", line 589, in spawn_worker
    worker.init_process()
  File "/home/ubuntu/virtualenv/vulndemo/lib/python3.10/site-packages/gunicorn/workers/ggevent.py", line 146, in init_process
    super().init_process()
  File "/home/ubuntu/virtualenv/vulndemo/lib/python3.10/site-packages/gunicorn/workers/base.py", line 134, in init_process
    self.load_wsgi()
  File "/home/ubuntu/virtualenv/vulndemo/lib/python3.10/site-packages/gunicorn/workers/base.py", line 146, in load_wsgi
    self.wsgi = self.app.wsgi()
  File "/home/ubuntu/virtualenv/vulndemo/lib/python3.10/site-packages/gunicorn/app/base.py", line 67, in wsgi
    self.callable = self.load()
  File "/home/ubuntu/virtualenv/vulndemo/lib/python3.10/site-packages/gunicorn/app/wsgiapp.py", line 58, in load
    return self.load_wsgiapp()
  File "/home/ubuntu/virtualenv/vulndemo/lib/python3.10/site-packages/gunicorn/app/wsgiapp.py", line 48, in load_wsgiapp
    return util.import_app(self.app_uri)
  File "/home/ubuntu/virtualenv/vulndemo/lib/python3.10/site-packages/gunicorn/util.py", line 359, in import_app
    mod = importlib.import_module(module)
  File "/usr/lib/python3.10/importlib/__init__.py", line 126, in import_module
    return _bootstrap._gcd_import(name[level:], package, level)
  File "<frozen importlib._bootstrap>", line 1050, in _gcd_import
  File "<frozen importlib._bootstrap>", line 1027, in _find_and_load
  File "<frozen importlib._bootstrap>", line 1006, in _find_and_load_unlocked
  File "<frozen importlib._bootstrap>", line 688, in _load_unlocked
  File "<frozen importlib._bootstrap_external>", line 883, in exec_module
  File "<frozen importlib._bootstrap>", line 241, in _call_with_frames_removed
  File "/home/ubuntu/work/app.py", line 7, in <module>
    from flask_cors import CORS, cross_origin
ModuleNotFoundError: No module named 'flask_cors'
[2022-12-02 15:38:35 +0800] [815136] [INFO] Worker exiting (pid: 815136)
Traceback (most recent call last):
  File "src/gevent/greenlet.py", line 908, in gevent._gevent_cgreenlet.Greenlet.run
  File "/home/ubuntu/virtualenv/vulndemo/lib/python3.10/site-packages/gunicorn/arbiter.py", line 242, in handle_chld
    self.reap_workers()
  File "/home/ubuntu/virtualenv/vulndemo/lib/python3.10/site-packages/gunicorn/arbiter.py", line 525, in reap_workers
    raise HaltServer(reason, self.WORKER_BOOT_ERROR)
gunicorn.errors.HaltServer: <HaltServer 'Worker failed to boot.' 3>
2022-12-02T07:38:35Z <Greenlet at 0x7f2b90eba700: <bound method Arbiter.handle_chld of <gunicorn.arbiter.Arbiter object at 0x7f2b90e99f00>>(17, None)> failed with HaltServer

Traceback (most recent call last):
  File "src/gevent/greenlet.py", line 908, in gevent._gevent_cgreenlet.Greenlet.run
  File "/home/ubuntu/virtualenv/vulndemo/lib/python3.10/site-packages/gunicorn/arbiter.py", line 242, in handle_chld
    self.reap_workers()
  File "/home/ubuntu/virtualenv/vulndemo/lib/python3.10/site-packages/gunicorn/arbiter.py", line 525, in reap_workers
    raise HaltServer(reason, self.WORKER_BOOT_ERROR)
gunicorn.errors.HaltServer: <HaltServer 'Worker failed to boot.' 3>
2022-12-02T07:38:35Z <Greenlet at 0x7f2b90eba700: <bound method Arbiter.handle_chld of <gunicorn.arbiter.Arbiter object at 0x7f2b90e99f00>>(17, None)> failed with HaltServer

Traceback (most recent call last):
  File "src/gevent/greenlet.py", line 908, in gevent._gevent_cgreenlet.Greenlet.run
  File "/home/ubuntu/virtualenv/vulndemo/lib/python3.10/site-packages/gunicorn/arbiter.py", line 242, in handle_chld
    self.reap_workers()
  File "/home/ubuntu/virtualenv/vulndemo/lib/python3.10/site-packages/gunicorn/arbiter.py", line 525, in reap_workers
    raise HaltServer(reason, self.WORKER_BOOT_ERROR)
gunicorn.errors.HaltServer: <HaltServer 'Worker failed to boot.' 3>
2022-12-02T07:38:35Z <Greenlet at 0x7f2b90eba700: <bound method Arbiter.handle_chld of <gunicorn.arbiter.Arbiter object at 0x7f2b90e99f00>>(17, None)> failed with HaltServer

[2022-12-02 15:39:05 +0800] [815053] [CRITICAL] WORKER TIMEOUT (pid:815134)
[2022-12-02 15:39:05 +0800] [815053] [CRITICAL] WORKER TIMEOUT (pid:815135)
[2022-12-02 15:39:05 +0800] [815053] [CRITICAL] WORKER TIMEOUT (pid:815136)
[2022-12-02 15:39:05 +0800] [815053] [CRITICAL] WORKER TIMEOUT (pid:815137)
[2022-12-02 15:39:05 +0800] [815225] [INFO] Booting worker with pid: 815225
[2022-12-02 15:39:05 +0800] [815226] [INFO] Booting worker with pid: 815226
[2022-12-02 15:39:05 +0800] [815225] [ERROR] Exception in worker process
Traceback (most recent call last):
  File "/home/ubuntu/virtualenv/vulndemo/lib/python3.10/site-packages/gunicorn/arbiter.py", line 589, in spawn_worker
    worker.init_process()
  File "/home/ubuntu/virtualenv/vulndemo/lib/python3.10/site-packages/gunicorn/workers/ggevent.py", line 146, in init_process
    super().init_process()
  File "/home/ubuntu/virtualenv/vulndemo/lib/python3.10/site-packages/gunicorn/workers/base.py", line 134, in init_process
    self.load_wsgi()
  File "/home/ubuntu/virtualenv/vulndemo/lib/python3.10/site-packages/gunicorn/workers/base.py", line 146, in load_wsgi
    self.wsgi = self.app.wsgi()
  File "/home/ubuntu/virtualenv/vulndemo/lib/python3.10/site-packages/gunicorn/app/base.py", line 67, in wsgi
    self.callable = self.load()
  File "/home/ubuntu/virtualenv/vulndemo/lib/python3.10/site-packages/gunicorn/app/wsgiapp.py", line 58, in load
    return self.load_wsgiapp()
  File "/home/ubuntu/virtualenv/vulndemo/lib/python3.10/site-packages/gunicorn/app/wsgiapp.py", line 48, in load_wsgiapp
    return util.import_app(self.app_uri)
  File "/home/ubuntu/virtualenv/vulndemo/lib/python3.10/site-packages/gunicorn/util.py", line 359, in import_app
    mod = importlib.import_module(module)
  File "/usr/lib/python3.10/importlib/__init__.py", line 126, in import_module
    return _bootstrap._gcd_import(name[level:], package, level)
  File "<frozen importlib._bootstrap>", line 1050, in _gcd_import
  File "<frozen importlib._bootstrap>", line 1027, in _find_and_load
  File "<frozen importlib._bootstrap>", line 1006, in _find_and_load_unlocked
  File "<frozen importlib._bootstrap>", line 688, in _load_unlocked
  File "<frozen importlib._bootstrap_external>", line 883, in exec_module
  File "<frozen importlib._bootstrap>", line 241, in _call_with_frames_removed
  File "/home/ubuntu/work/app.py", line 7, in <module>
    from flask_cors import CORS, cross_origin
ModuleNotFoundError: No module named 'flask_cors'
[2022-12-02 15:39:05 +0800] [815225] [INFO] Worker exiting (pid: 815225)
[2022-12-02 15:39:05 +0800] [815228] [INFO] Booting worker with pid: 815228
[2022-12-02 15:39:05 +0800] [815229] [INFO] Booting worker with pid: 815229
Traceback (most recent call last):
  File "src/gevent/greenlet.py", line 908, in gevent._gevent_cgreenlet.Greenlet.run
  File "/home/ubuntu/virtualenv/vulndemo/lib/python3.10/site-packages/gunicorn/arbiter.py", line 242, in handle_chld
    self.reap_workers()
  File "/home/ubuntu/virtualenv/vulndemo/lib/python3.10/site-packages/gunicorn/arbiter.py", line 525, in reap_workers
    raise HaltServer(reason, self.WORKER_BOOT_ERROR)
gunicorn.errors.HaltServer: <HaltServer 'Worker failed to boot.' 3>
2022-12-02T07:39:05Z <Greenlet at 0x7f2b90eba700: <bound method Arbiter.handle_chld of <gunicorn.arbiter.Arbiter object at 0x7f2b90e99f00>>(17, None)> failed with HaltServer

[2022-12-02 15:39:05 +0800] [815226] [ERROR] Exception in worker process
Traceback (most recent call last):
  File "/home/ubuntu/virtualenv/vulndemo/lib/python3.10/site-packages/gunicorn/arbiter.py", line 589, in spawn_worker
    worker.init_process()
  File "/home/ubuntu/virtualenv/vulndemo/lib/python3.10/site-packages/gunicorn/workers/ggevent.py", line 146, in init_process
    super().init_process()
  File "/home/ubuntu/virtualenv/vulndemo/lib/python3.10/site-packages/gunicorn/workers/base.py", line 134, in init_process
    self.load_wsgi()
  File "/home/ubuntu/virtualenv/vulndemo/lib/python3.10/site-packages/gunicorn/workers/base.py", line 146, in load_wsgi
    self.wsgi = self.app.wsgi()
  File "/home/ubuntu/virtualenv/vulndemo/lib/python3.10/site-packages/gunicorn/app/base.py", line 67, in wsgi
    self.callable = self.load()
  File "/home/ubuntu/virtualenv/vulndemo/lib/python3.10/site-packages/gunicorn/app/wsgiapp.py", line 58, in load
    return self.load_wsgiapp()
  File "/home/ubuntu/virtualenv/vulndemo/lib/python3.10/site-packages/gunicorn/app/wsgiapp.py", line 48, in load_wsgiapp
    return util.import_app(self.app_uri)
  File "/home/ubuntu/virtualenv/vulndemo/lib/python3.10/site-packages/gunicorn/util.py", line 359, in import_app
    mod = importlib.import_module(module)
  File "/usr/lib/python3.10/importlib/__init__.py", line 126, in import_module
    return _bootstrap._gcd_import(name[level:], package, level)
  File "<frozen importlib._bootstrap>", line 1050, in _gcd_import
  File "<frozen importlib._bootstrap>", line 1027, in _find_and_load
  File "<frozen importlib._bootstrap>", line 1006, in _find_and_load_unlocked
  File "<frozen importlib._bootstrap>", line 688, in _load_unlocked
  File "<frozen importlib._bootstrap_external>", line 883, in exec_module
  File "<frozen importlib._bootstrap>", line 241, in _call_with_frames_removed
  File "/home/ubuntu/work/app.py", line 7, in <module>
    from flask_cors import CORS, cross_origin
ModuleNotFoundError: No module named 'flask_cors'
[2022-12-02 15:39:05 +0800] [815226] [INFO] Worker exiting (pid: 815226)
Traceback (most recent call last):
  File "src/gevent/greenlet.py", line 908, in gevent._gevent_cgreenlet.Greenlet.run
  File "/home/ubuntu/virtualenv/vulndemo/lib/python3.10/site-packages/gunicorn/arbiter.py", line 242, in handle_chld
    self.reap_workers()
  File "/home/ubuntu/virtualenv/vulndemo/lib/python3.10/site-packages/gunicorn/arbiter.py", line 525, in reap_workers
    raise HaltServer(reason, self.WORKER_BOOT_ERROR)
gunicorn.errors.HaltServer: <HaltServer 'Worker failed to boot.' 3>
2022-12-02T07:39:05Z <Greenlet at 0x7f2b90eba700: <bound method Arbiter.handle_chld of <gunicorn.arbiter.Arbiter object at 0x7f2b90e99f00>>(17, None)> failed with HaltServer

[2022-12-02 15:39:05 +0800] [815228] [ERROR] Exception in worker process
Traceback (most recent call last):
  File "/home/ubuntu/virtualenv/vulndemo/lib/python3.10/site-packages/gunicorn/arbiter.py", line 589, in spawn_worker
    worker.init_process()
  File "/home/ubuntu/virtualenv/vulndemo/lib/python3.10/site-packages/gunicorn/workers/ggevent.py", line 146, in init_process
    super().init_process()
  File "/home/ubuntu/virtualenv/vulndemo/lib/python3.10/site-packages/gunicorn/workers/base.py", line 134, in init_process
    self.load_wsgi()
  File "/home/ubuntu/virtualenv/vulndemo/lib/python3.10/site-packages/gunicorn/workers/base.py", line 146, in load_wsgi
    self.wsgi = self.app.wsgi()
  File "/home/ubuntu/virtualenv/vulndemo/lib/python3.10/site-packages/gunicorn/app/base.py", line 67, in wsgi
    self.callable = self.load()
  File "/home/ubuntu/virtualenv/vulndemo/lib/python3.10/site-packages/gunicorn/app/wsgiapp.py", line 58, in load
    return self.load_wsgiapp()
  File "/home/ubuntu/virtualenv/vulndemo/lib/python3.10/site-packages/gunicorn/app/wsgiapp.py", line 48, in load_wsgiapp
    return util.import_app(self.app_uri)
  File "/home/ubuntu/virtualenv/vulndemo/lib/python3.10/site-packages/gunicorn/util.py", line 359, in import_app
    mod = importlib.import_module(module)
  File "/usr/lib/python3.10/importlib/__init__.py", line 126, in import_module
    return _bootstrap._gcd_import(name[level:], package, level)
  File "<frozen importlib._bootstrap>", line 1050, in _gcd_import
  File "<frozen importlib._bootstrap>", line 1027, in _find_and_load
  File "<frozen importlib._bootstrap>", line 1006, in _find_and_load_unlocked
  File "<frozen importlib._bootstrap>", line 688, in _load_unlocked
  File "<frozen importlib._bootstrap_external>", line 883, in exec_module
  File "<frozen importlib._bootstrap>", line 241, in _call_with_frames_removed
  File "/home/ubuntu/work/app.py", line 7, in <module>
    from flask_cors import CORS, cross_origin
ModuleNotFoundError: No module named 'flask_cors'
[2022-12-02 15:39:05 +0800] [815228] [INFO] Worker exiting (pid: 815228)
[2022-12-02 15:39:05 +0800] [815229] [ERROR] Exception in worker process
Traceback (most recent call last):
  File "/home/ubuntu/virtualenv/vulndemo/lib/python3.10/site-packages/gunicorn/arbiter.py", line 589, in spawn_worker
    worker.init_process()
  File "/home/ubuntu/virtualenv/vulndemo/lib/python3.10/site-packages/gunicorn/workers/ggevent.py", line 146, in init_process
    super().init_process()
  File "/home/ubuntu/virtualenv/vulndemo/lib/python3.10/site-packages/gunicorn/workers/base.py", line 134, in init_process
    self.load_wsgi()
  File "/home/ubuntu/virtualenv/vulndemo/lib/python3.10/site-packages/gunicorn/workers/base.py", line 146, in load_wsgi
    self.wsgi = self.app.wsgi()
  File "/home/ubuntu/virtualenv/vulndemo/lib/python3.10/site-packages/gunicorn/app/base.py", line 67, in wsgi
    self.callable = self.load()
  File "/home/ubuntu/virtualenv/vulndemo/lib/python3.10/site-packages/gunicorn/app/wsgiapp.py", line 58, in load
    return self.load_wsgiapp()
  File "/home/ubuntu/virtualenv/vulndemo/lib/python3.10/site-packages/gunicorn/app/wsgiapp.py", line 48, in load_wsgiapp
    return util.import_app(self.app_uri)
  File "/home/ubuntu/virtualenv/vulndemo/lib/python3.10/site-packages/gunicorn/util.py", line 359, in import_app
    mod = importlib.import_module(module)
  File "/usr/lib/python3.10/importlib/__init__.py", line 126, in import_module
    return _bootstrap._gcd_import(name[level:], package, level)
  File "<frozen importlib._bootstrap>", line 1050, in _gcd_import
  File "<frozen importlib._bootstrap>", line 1027, in _find_and_load
  File "<frozen importlib._bootstrap>", line 1006, in _find_and_load_unlocked
  File "<frozen importlib._bootstrap>", line 688, in _load_unlocked
  File "<frozen importlib._bootstrap_external>", line 883, in exec_module
  File "<frozen importlib._bootstrap>", line 241, in _call_with_frames_removed
  File "/home/ubuntu/work/app.py", line 7, in <module>
    from flask_cors import CORS, cross_origin
ModuleNotFoundError: No module named 'flask_cors'
[2022-12-02 15:39:05 +0800] [815229] [INFO] Worker exiting (pid: 815229)
Traceback (most recent call last):
  File "src/gevent/greenlet.py", line 908, in gevent._gevent_cgreenlet.Greenlet.run
  File "/home/ubuntu/virtualenv/vulndemo/lib/python3.10/site-packages/gunicorn/arbiter.py", line 242, in handle_chld
    self.reap_workers()
  File "/home/ubuntu/virtualenv/vulndemo/lib/python3.10/site-packages/gunicorn/arbiter.py", line 525, in reap_workers
    raise HaltServer(reason, self.WORKER_BOOT_ERROR)
gunicorn.errors.HaltServer: <HaltServer 'Worker failed to boot.' 3>
2022-12-02T07:39:05Z <Greenlet at 0x7f2b90eba700: <bound method Arbiter.handle_chld of <gunicorn.arbiter.Arbiter object at 0x7f2b90e99f00>>(17, None)> failed with HaltServer

Traceback (most recent call last):
  File "src/gevent/greenlet.py", line 908, in gevent._gevent_cgreenlet.Greenlet.run
  File "/home/ubuntu/virtualenv/vulndemo/lib/python3.10/site-packages/gunicorn/arbiter.py", line 242, in handle_chld
    self.reap_workers()
  File "/home/ubuntu/virtualenv/vulndemo/lib/python3.10/site-packages/gunicorn/arbiter.py", line 525, in reap_workers
    raise HaltServer(reason, self.WORKER_BOOT_ERROR)
gunicorn.errors.HaltServer: <HaltServer 'Worker failed to boot.' 3>
2022-12-02T07:39:05Z <Greenlet at 0x7f2b90eba700: <bound method Arbiter.handle_chld of <gunicorn.arbiter.Arbiter object at 0x7f2b90e99f00>>(17, None)> failed with HaltServer

[2022-12-02 15:39:07 +0800] [815053] [INFO] Handling signal: term
[2022-12-02 15:39:07 +0800] [815053] [INFO] Shutting down: Master
[2022-12-02 15:39:34 +0800] [815296] [DEBUG] Current configuration:
  config: /home/ubuntu/work/gconfig.py
  wsgi_app: None
  bind: ['0.0.0.0:5000']
  backlog: 2048
  workers: 4
  worker_class: gevent
  threads: 1
  worker_connections: 1000
  max_requests: 0
  max_requests_jitter: 0
  timeout: 30
  graceful_timeout: 30
  keepalive: 2
  limit_request_line: 4094
  limit_request_fields: 100
  limit_request_field_size: 8190
  reload: False
  reload_engine: auto
  reload_extra_files: []
  spew: False
  check_config: False
  print_config: False
  preload_app: False
  sendfile: None
  reuse_port: False
  chdir: /home/ubuntu/work
  daemon: False
  raw_env: []
  pidfile: log/gunicorn.pid
  worker_tmp_dir: None
  user: 0
  group: 0
  umask: 0
  initgroups: False
  tmp_upload_dir: None
  secure_scheme_headers: {'X-FORWARDED-PROTOCOL': 'ssl', 'X-FORWARDED-PROTO': 'https', 'X-FORWARDED-SSL': 'on'}
  forwarded_allow_ips: ['127.0.0.1']
  accesslog: None
  disable_redirect_access_to_syslog: False
  access_log_format: %(h)s %(l)s %(u)s %(t)s "%(r)s" %(s)s %(b)s "%(f)s" "%(a)s"
  errorlog: -
  loglevel: debug
  capture_output: False
  logger_class: gunicorn.glogging.Logger
  logconfig: None
  logconfig_dict: {}
  syslog_addr: udp://localhost:514
  syslog: False
  syslog_prefix: None
  syslog_facility: user
  enable_stdio_inheritance: False
  statsd_host: None
  dogstatsd_tags: 
  statsd_prefix: 
  proc_name: None
  default_proc_name: app:app
  pythonpath: None
  paste: None
  on_starting: <function OnStarting.on_starting at 0x7f234424e4d0>
  on_reload: <function OnReload.on_reload at 0x7f234424e5f0>
  when_ready: <function WhenReady.when_ready at 0x7f234424e710>
  pre_fork: <function Prefork.pre_fork at 0x7f234424e830>
  post_fork: <function Postfork.post_fork at 0x7f234424e950>
  post_worker_init: <function PostWorkerInit.post_worker_init at 0x7f234424ea70>
  worker_int: <function WorkerInt.worker_int at 0x7f234424eb90>
  worker_abort: <function WorkerAbort.worker_abort at 0x7f234424ecb0>
  pre_exec: <function PreExec.pre_exec at 0x7f234424edd0>
  pre_request: <function PreRequest.pre_request at 0x7f234424eef0>
  post_request: <function PostRequest.post_request at 0x7f234424ef80>
  child_exit: <function ChildExit.child_exit at 0x7f234424f0a0>
  worker_exit: <function WorkerExit.worker_exit at 0x7f234424f1c0>
  nworkers_changed: <function NumWorkersChanged.nworkers_changed at 0x7f234424f2e0>
  on_exit: <function OnExit.on_exit at 0x7f234424f400>
  proxy_protocol: False
  proxy_allow_ips: ['127.0.0.1']
  keyfile: None
  certfile: None
  ssl_version: 2
  cert_reqs: 0
  ca_certs: None
  suppress_ragged_eofs: True
  do_handshake_on_connect: False
  ciphers: None
  raw_paste_global_conf: []
  strip_header_spaces: False
[2022-12-02 15:39:34 +0800] [815296] [INFO] Starting gunicorn 20.1.0
[2022-12-02 15:39:34 +0800] [815296] [DEBUG] Arbiter booted
[2022-12-02 15:39:34 +0800] [815296] [INFO] Listening at: http://0.0.0.0:5000 (815296)
[2022-12-02 15:39:34 +0800] [815296] [INFO] Using worker: gevent
[2022-12-02 15:39:34 +0800] [815297] [INFO] Booting worker with pid: 815297
[2022-12-02 15:39:34 +0800] [815298] [INFO] Booting worker with pid: 815298
[2022-12-02 15:39:34 +0800] [815299] [INFO] Booting worker with pid: 815299
[2022-12-02 15:39:34 +0800] [815300] [INFO] Booting worker with pid: 815300
[2022-12-02 15:39:34 +0800] [815296] [DEBUG] 4 workers
[2022-12-02 15:39:34 +0800] [815297] [ERROR] Exception in worker process
Traceback (most recent call last):
  File "/home/ubuntu/virtualenv/vulndemo/lib/python3.10/site-packages/gunicorn/arbiter.py", line 589, in spawn_worker
    worker.init_process()
  File "/home/ubuntu/virtualenv/vulndemo/lib/python3.10/site-packages/gunicorn/workers/ggevent.py", line 146, in init_process
    super().init_process()
  File "/home/ubuntu/virtualenv/vulndemo/lib/python3.10/site-packages/gunicorn/workers/base.py", line 134, in init_process
    self.load_wsgi()
  File "/home/ubuntu/virtualenv/vulndemo/lib/python3.10/site-packages/gunicorn/workers/base.py", line 146, in load_wsgi
    self.wsgi = self.app.wsgi()
  File "/home/ubuntu/virtualenv/vulndemo/lib/python3.10/site-packages/gunicorn/app/base.py", line 67, in wsgi
    self.callable = self.load()
  File "/home/ubuntu/virtualenv/vulndemo/lib/python3.10/site-packages/gunicorn/app/wsgiapp.py", line 58, in load
    return self.load_wsgiapp()
  File "/home/ubuntu/virtualenv/vulndemo/lib/python3.10/site-packages/gunicorn/app/wsgiapp.py", line 48, in load_wsgiapp
    return util.import_app(self.app_uri)
  File "/home/ubuntu/virtualenv/vulndemo/lib/python3.10/site-packages/gunicorn/util.py", line 359, in import_app
    mod = importlib.import_module(module)
  File "/usr/lib/python3.10/importlib/__init__.py", line 126, in import_module
    return _bootstrap._gcd_import(name[level:], package, level)
  File "<frozen importlib._bootstrap>", line 1050, in _gcd_import
  File "<frozen importlib._bootstrap>", line 1027, in _find_and_load
  File "<frozen importlib._bootstrap>", line 1006, in _find_and_load_unlocked
  File "<frozen importlib._bootstrap>", line 688, in _load_unlocked
  File "<frozen importlib._bootstrap_external>", line 883, in exec_module
  File "<frozen importlib._bootstrap>", line 241, in _call_with_frames_removed
  File "/home/ubuntu/work/app.py", line 7, in <module>
    from flask_cors import CORS, cross_origin
ModuleNotFoundError: No module named 'flask_cors'
[2022-12-02 15:39:34 +0800] [815297] [INFO] Worker exiting (pid: 815297)
Traceback (most recent call last):
  File "src/gevent/greenlet.py", line 908, in gevent._gevent_cgreenlet.Greenlet.run
  File "/home/ubuntu/virtualenv/vulndemo/lib/python3.10/site-packages/gunicorn/arbiter.py", line 242, in handle_chld
    self.reap_workers()
  File "/home/ubuntu/virtualenv/vulndemo/lib/python3.10/site-packages/gunicorn/arbiter.py", line 525, in reap_workers
    raise HaltServer(reason, self.WORKER_BOOT_ERROR)
gunicorn.errors.HaltServer: <HaltServer 'Worker failed to boot.' 3>
2022-12-02T07:39:35Z <Greenlet at 0x7f2343a9a700: <bound method Arbiter.handle_chld of <gunicorn.arbiter.Arbiter object at 0x7f2343a79f90>>(17, None)> failed with HaltServer

[2022-12-02 15:39:35 +0800] [815298] [ERROR] Exception in worker process
Traceback (most recent call last):
  File "/home/ubuntu/virtualenv/vulndemo/lib/python3.10/site-packages/gunicorn/arbiter.py", line 589, in spawn_worker
    worker.init_process()
  File "/home/ubuntu/virtualenv/vulndemo/lib/python3.10/site-packages/gunicorn/workers/ggevent.py", line 146, in init_process
    super().init_process()
  File "/home/ubuntu/virtualenv/vulndemo/lib/python3.10/site-packages/gunicorn/workers/base.py", line 134, in init_process
    self.load_wsgi()
  File "/home/ubuntu/virtualenv/vulndemo/lib/python3.10/site-packages/gunicorn/workers/base.py", line 146, in load_wsgi
    self.wsgi = self.app.wsgi()
  File "/home/ubuntu/virtualenv/vulndemo/lib/python3.10/site-packages/gunicorn/app/base.py", line 67, in wsgi
    self.callable = self.load()
  File "/home/ubuntu/virtualenv/vulndemo/lib/python3.10/site-packages/gunicorn/app/wsgiapp.py", line 58, in load
    return self.load_wsgiapp()
  File "/home/ubuntu/virtualenv/vulndemo/lib/python3.10/site-packages/gunicorn/app/wsgiapp.py", line 48, in load_wsgiapp
    return util.import_app(self.app_uri)
  File "/home/ubuntu/virtualenv/vulndemo/lib/python3.10/site-packages/gunicorn/util.py", line 359, in import_app
    mod = importlib.import_module(module)
  File "/usr/lib/python3.10/importlib/__init__.py", line 126, in import_module
    return _bootstrap._gcd_import(name[level:], package, level)
  File "<frozen importlib._bootstrap>", line 1050, in _gcd_import
  File "<frozen importlib._bootstrap>", line 1027, in _find_and_load
  File "<frozen importlib._bootstrap>", line 1006, in _find_and_load_unlocked
  File "<frozen importlib._bootstrap>", line 688, in _load_unlocked
  File "<frozen importlib._bootstrap_external>", line 883, in exec_module
  File "<frozen importlib._bootstrap>", line 241, in _call_with_frames_removed
  File "/home/ubuntu/work/app.py", line 7, in <module>
    from flask_cors import CORS, cross_origin
ModuleNotFoundError: No module named 'flask_cors'
[2022-12-02 15:39:35 +0800] [815298] [INFO] Worker exiting (pid: 815298)
[2022-12-02 15:39:35 +0800] [815300] [ERROR] Exception in worker process
Traceback (most recent call last):
  File "/home/ubuntu/virtualenv/vulndemo/lib/python3.10/site-packages/gunicorn/arbiter.py", line 589, in spawn_worker
    worker.init_process()
  File "/home/ubuntu/virtualenv/vulndemo/lib/python3.10/site-packages/gunicorn/workers/ggevent.py", line 146, in init_process
    super().init_process()
  File "/home/ubuntu/virtualenv/vulndemo/lib/python3.10/site-packages/gunicorn/workers/base.py", line 134, in init_process
    self.load_wsgi()
  File "/home/ubuntu/virtualenv/vulndemo/lib/python3.10/site-packages/gunicorn/workers/base.py", line 146, in load_wsgi
    self.wsgi = self.app.wsgi()
  File "/home/ubuntu/virtualenv/vulndemo/lib/python3.10/site-packages/gunicorn/app/base.py", line 67, in wsgi
    self.callable = self.load()
  File "/home/ubuntu/virtualenv/vulndemo/lib/python3.10/site-packages/gunicorn/app/wsgiapp.py", line 58, in load
    return self.load_wsgiapp()
  File "/home/ubuntu/virtualenv/vulndemo/lib/python3.10/site-packages/gunicorn/app/wsgiapp.py", line 48, in load_wsgiapp
    return util.import_app(self.app_uri)
  File "/home/ubuntu/virtualenv/vulndemo/lib/python3.10/site-packages/gunicorn/util.py", line 359, in import_app
    mod = importlib.import_module(module)
  File "/usr/lib/python3.10/importlib/__init__.py", line 126, in import_module
    return _bootstrap._gcd_import(name[level:], package, level)
  File "<frozen importlib._bootstrap>", line 1050, in _gcd_import
  File "<frozen importlib._bootstrap>", line 1027, in _find_and_load
  File "<frozen importlib._bootstrap>", line 1006, in _find_and_load_unlocked
  File "<frozen importlib._bootstrap>", line 688, in _load_unlocked
  File "<frozen importlib._bootstrap_external>", line 883, in exec_module
  File "<frozen importlib._bootstrap>", line 241, in _call_with_frames_removed
  File "/home/ubuntu/work/app.py", line 7, in <module>
    from flask_cors import CORS, cross_origin
ModuleNotFoundError: No module named 'flask_cors'
[2022-12-02 15:39:35 +0800] [815300] [INFO] Worker exiting (pid: 815300)
[2022-12-02 15:39:35 +0800] [815299] [ERROR] Exception in worker process
Traceback (most recent call last):
  File "/home/ubuntu/virtualenv/vulndemo/lib/python3.10/site-packages/gunicorn/arbiter.py", line 589, in spawn_worker
    worker.init_process()
  File "/home/ubuntu/virtualenv/vulndemo/lib/python3.10/site-packages/gunicorn/workers/ggevent.py", line 146, in init_process
    super().init_process()
  File "/home/ubuntu/virtualenv/vulndemo/lib/python3.10/site-packages/gunicorn/workers/base.py", line 134, in init_process
    self.load_wsgi()
  File "/home/ubuntu/virtualenv/vulndemo/lib/python3.10/site-packages/gunicorn/workers/base.py", line 146, in load_wsgi
    self.wsgi = self.app.wsgi()
  File "/home/ubuntu/virtualenv/vulndemo/lib/python3.10/site-packages/gunicorn/app/base.py", line 67, in wsgi
    self.callable = self.load()
  File "/home/ubuntu/virtualenv/vulndemo/lib/python3.10/site-packages/gunicorn/app/wsgiapp.py", line 58, in load
    return self.load_wsgiapp()
  File "/home/ubuntu/virtualenv/vulndemo/lib/python3.10/site-packages/gunicorn/app/wsgiapp.py", line 48, in load_wsgiapp
    return util.import_app(self.app_uri)
  File "/home/ubuntu/virtualenv/vulndemo/lib/python3.10/site-packages/gunicorn/util.py", line 359, in import_app
    mod = importlib.import_module(module)
  File "/usr/lib/python3.10/importlib/__init__.py", line 126, in import_module
    return _bootstrap._gcd_import(name[level:], package, level)
  File "<frozen importlib._bootstrap>", line 1050, in _gcd_import
  File "<frozen importlib._bootstrap>", line 1027, in _find_and_load
  File "<frozen importlib._bootstrap>", line 1006, in _find_and_load_unlocked
  File "<frozen importlib._bootstrap>", line 688, in _load_unlocked
  File "<frozen importlib._bootstrap_external>", line 883, in exec_module
  File "<frozen importlib._bootstrap>", line 241, in _call_with_frames_removed
  File "/home/ubuntu/work/app.py", line 7, in <module>
    from flask_cors import CORS, cross_origin
ModuleNotFoundError: No module named 'flask_cors'
[2022-12-02 15:39:35 +0800] [815299] [INFO] Worker exiting (pid: 815299)
Traceback (most recent call last):
  File "src/gevent/greenlet.py", line 908, in gevent._gevent_cgreenlet.Greenlet.run
  File "/home/ubuntu/virtualenv/vulndemo/lib/python3.10/site-packages/gunicorn/arbiter.py", line 242, in handle_chld
    self.reap_workers()
  File "/home/ubuntu/virtualenv/vulndemo/lib/python3.10/site-packages/gunicorn/arbiter.py", line 525, in reap_workers
    raise HaltServer(reason, self.WORKER_BOOT_ERROR)
gunicorn.errors.HaltServer: <HaltServer 'Worker failed to boot.' 3>
2022-12-02T07:39:35Z <Greenlet at 0x7f2343a9a700: <bound method Arbiter.handle_chld of <gunicorn.arbiter.Arbiter object at 0x7f2343a79f90>>(17, None)> failed with HaltServer

Traceback (most recent call last):
  File "src/gevent/greenlet.py", line 908, in gevent._gevent_cgreenlet.Greenlet.run
  File "/home/ubuntu/virtualenv/vulndemo/lib/python3.10/site-packages/gunicorn/arbiter.py", line 242, in handle_chld
    self.reap_workers()
  File "/home/ubuntu/virtualenv/vulndemo/lib/python3.10/site-packages/gunicorn/arbiter.py", line 525, in reap_workers
    raise HaltServer(reason, self.WORKER_BOOT_ERROR)
gunicorn.errors.HaltServer: <HaltServer 'Worker failed to boot.' 3>
2022-12-02T07:39:35Z <Greenlet at 0x7f2343a9a700: <bound method Arbiter.handle_chld of <gunicorn.arbiter.Arbiter object at 0x7f2343a79f90>>(17, None)> failed with HaltServer

Traceback (most recent call last):
  File "src/gevent/greenlet.py", line 908, in gevent._gevent_cgreenlet.Greenlet.run
  File "/home/ubuntu/virtualenv/vulndemo/lib/python3.10/site-packages/gunicorn/arbiter.py", line 242, in handle_chld
    self.reap_workers()
  File "/home/ubuntu/virtualenv/vulndemo/lib/python3.10/site-packages/gunicorn/arbiter.py", line 525, in reap_workers
    raise HaltServer(reason, self.WORKER_BOOT_ERROR)
gunicorn.errors.HaltServer: <HaltServer 'Worker failed to boot.' 3>
2022-12-02T07:39:35Z <Greenlet at 0x7f2343a9a700: <bound method Arbiter.handle_chld of <gunicorn.arbiter.Arbiter object at 0x7f2343a79f90>>(17, None)> failed with HaltServer

[2022-12-02 15:40:04 +0800] [815296] [CRITICAL] WORKER TIMEOUT (pid:815297)
[2022-12-02 15:40:04 +0800] [815296] [CRITICAL] WORKER TIMEOUT (pid:815298)
[2022-12-02 15:40:04 +0800] [815296] [CRITICAL] WORKER TIMEOUT (pid:815299)
[2022-12-02 15:40:04 +0800] [815296] [CRITICAL] WORKER TIMEOUT (pid:815300)
[2022-12-02 15:40:04 +0800] [815398] [INFO] Booting worker with pid: 815398
[2022-12-02 15:40:05 +0800] [815399] [INFO] Booting worker with pid: 815399
[2022-12-02 15:40:05 +0800] [815398] [ERROR] Exception in worker process
Traceback (most recent call last):
  File "/home/ubuntu/virtualenv/vulndemo/lib/python3.10/site-packages/gunicorn/arbiter.py", line 589, in spawn_worker
    worker.init_process()
  File "/home/ubuntu/virtualenv/vulndemo/lib/python3.10/site-packages/gunicorn/workers/ggevent.py", line 146, in init_process
    super().init_process()
  File "/home/ubuntu/virtualenv/vulndemo/lib/python3.10/site-packages/gunicorn/workers/base.py", line 134, in init_process
    self.load_wsgi()
  File "/home/ubuntu/virtualenv/vulndemo/lib/python3.10/site-packages/gunicorn/workers/base.py", line 146, in load_wsgi
    self.wsgi = self.app.wsgi()
  File "/home/ubuntu/virtualenv/vulndemo/lib/python3.10/site-packages/gunicorn/app/base.py", line 67, in wsgi
    self.callable = self.load()
  File "/home/ubuntu/virtualenv/vulndemo/lib/python3.10/site-packages/gunicorn/app/wsgiapp.py", line 58, in load
    return self.load_wsgiapp()
  File "/home/ubuntu/virtualenv/vulndemo/lib/python3.10/site-packages/gunicorn/app/wsgiapp.py", line 48, in load_wsgiapp
    return util.import_app(self.app_uri)
  File "/home/ubuntu/virtualenv/vulndemo/lib/python3.10/site-packages/gunicorn/util.py", line 359, in import_app
    mod = importlib.import_module(module)
  File "/usr/lib/python3.10/importlib/__init__.py", line 126, in import_module
    return _bootstrap._gcd_import(name[level:], package, level)
  File "<frozen importlib._bootstrap>", line 1050, in _gcd_import
  File "<frozen importlib._bootstrap>", line 1027, in _find_and_load
  File "<frozen importlib._bootstrap>", line 1006, in _find_and_load_unlocked
  File "<frozen importlib._bootstrap>", line 688, in _load_unlocked
  File "<frozen importlib._bootstrap_external>", line 883, in exec_module
  File "<frozen importlib._bootstrap>", line 241, in _call_with_frames_removed
  File "/home/ubuntu/work/app.py", line 7, in <module>
    from flask_cors import CORS, cross_origin
ModuleNotFoundError: No module named 'flask_cors'
[2022-12-02 15:40:05 +0800] [815398] [INFO] Worker exiting (pid: 815398)
[2022-12-02 15:40:05 +0800] [815401] [INFO] Booting worker with pid: 815401
[2022-12-02 15:40:05 +0800] [815402] [INFO] Booting worker with pid: 815402
Traceback (most recent call last):
  File "src/gevent/greenlet.py", line 908, in gevent._gevent_cgreenlet.Greenlet.run
  File "/home/ubuntu/virtualenv/vulndemo/lib/python3.10/site-packages/gunicorn/arbiter.py", line 242, in handle_chld
    self.reap_workers()
  File "/home/ubuntu/virtualenv/vulndemo/lib/python3.10/site-packages/gunicorn/arbiter.py", line 525, in reap_workers
    raise HaltServer(reason, self.WORKER_BOOT_ERROR)
gunicorn.errors.HaltServer: <HaltServer 'Worker failed to boot.' 3>
2022-12-02T07:40:05Z <Greenlet at 0x7f2343a9a700: <bound method Arbiter.handle_chld of <gunicorn.arbiter.Arbiter object at 0x7f2343a79f90>>(17, None)> failed with HaltServer

[2022-12-02 15:40:05 +0800] [815399] [ERROR] Exception in worker process
Traceback (most recent call last):
  File "/home/ubuntu/virtualenv/vulndemo/lib/python3.10/site-packages/gunicorn/arbiter.py", line 589, in spawn_worker
    worker.init_process()
  File "/home/ubuntu/virtualenv/vulndemo/lib/python3.10/site-packages/gunicorn/workers/ggevent.py", line 146, in init_process
    super().init_process()
  File "/home/ubuntu/virtualenv/vulndemo/lib/python3.10/site-packages/gunicorn/workers/base.py", line 134, in init_process
    self.load_wsgi()
  File "/home/ubuntu/virtualenv/vulndemo/lib/python3.10/site-packages/gunicorn/workers/base.py", line 146, in load_wsgi
    self.wsgi = self.app.wsgi()
  File "/home/ubuntu/virtualenv/vulndemo/lib/python3.10/site-packages/gunicorn/app/base.py", line 67, in wsgi
    self.callable = self.load()
  File "/home/ubuntu/virtualenv/vulndemo/lib/python3.10/site-packages/gunicorn/app/wsgiapp.py", line 58, in load
    return self.load_wsgiapp()
  File "/home/ubuntu/virtualenv/vulndemo/lib/python3.10/site-packages/gunicorn/app/wsgiapp.py", line 48, in load_wsgiapp
    return util.import_app(self.app_uri)
  File "/home/ubuntu/virtualenv/vulndemo/lib/python3.10/site-packages/gunicorn/util.py", line 359, in import_app
    mod = importlib.import_module(module)
  File "/usr/lib/python3.10/importlib/__init__.py", line 126, in import_module
    return _bootstrap._gcd_import(name[level:], package, level)
  File "<frozen importlib._bootstrap>", line 1050, in _gcd_import
  File "<frozen importlib._bootstrap>", line 1027, in _find_and_load
  File "<frozen importlib._bootstrap>", line 1006, in _find_and_load_unlocked
  File "<frozen importlib._bootstrap>", line 688, in _load_unlocked
  File "<frozen importlib._bootstrap_external>", line 883, in exec_module
  File "<frozen importlib._bootstrap>", line 241, in _call_with_frames_removed
  File "/home/ubuntu/work/app.py", line 7, in <module>
    from flask_cors import CORS, cross_origin
ModuleNotFoundError: No module named 'flask_cors'
[2022-12-02 15:40:05 +0800] [815399] [INFO] Worker exiting (pid: 815399)
[2022-12-02 15:40:05 +0800] [815401] [ERROR] Exception in worker process
Traceback (most recent call last):
  File "/home/ubuntu/virtualenv/vulndemo/lib/python3.10/site-packages/gunicorn/arbiter.py", line 589, in spawn_worker
    worker.init_process()
  File "/home/ubuntu/virtualenv/vulndemo/lib/python3.10/site-packages/gunicorn/workers/ggevent.py", line 146, in init_process
    super().init_process()
  File "/home/ubuntu/virtualenv/vulndemo/lib/python3.10/site-packages/gunicorn/workers/base.py", line 134, in init_process
    self.load_wsgi()
  File "/home/ubuntu/virtualenv/vulndemo/lib/python3.10/site-packages/gunicorn/workers/base.py", line 146, in load_wsgi
    self.wsgi = self.app.wsgi()
  File "/home/ubuntu/virtualenv/vulndemo/lib/python3.10/site-packages/gunicorn/app/base.py", line 67, in wsgi
    self.callable = self.load()
  File "/home/ubuntu/virtualenv/vulndemo/lib/python3.10/site-packages/gunicorn/app/wsgiapp.py", line 58, in load
    return self.load_wsgiapp()
  File "/home/ubuntu/virtualenv/vulndemo/lib/python3.10/site-packages/gunicorn/app/wsgiapp.py", line 48, in load_wsgiapp
    return util.import_app(self.app_uri)
  File "/home/ubuntu/virtualenv/vulndemo/lib/python3.10/site-packages/gunicorn/util.py", line 359, in import_app
    mod = importlib.import_module(module)
  File "/usr/lib/python3.10/importlib/__init__.py", line 126, in import_module
    return _bootstrap._gcd_import(name[level:], package, level)
  File "<frozen importlib._bootstrap>", line 1050, in _gcd_import
  File "<frozen importlib._bootstrap>", line 1027, in _find_and_load
  File "<frozen importlib._bootstrap>", line 1006, in _find_and_load_unlocked
  File "<frozen importlib._bootstrap>", line 688, in _load_unlocked
  File "<frozen importlib._bootstrap_external>", line 883, in exec_module
  File "<frozen importlib._bootstrap>", line 241, in _call_with_frames_removed
  File "/home/ubuntu/work/app.py", line 7, in <module>
    from flask_cors import CORS, cross_origin
ModuleNotFoundError: No module named 'flask_cors'
[2022-12-02 15:40:05 +0800] [815401] [INFO] Worker exiting (pid: 815401)
[2022-12-02 15:40:05 +0800] [815402] [ERROR] Exception in worker process
Traceback (most recent call last):
  File "/home/ubuntu/virtualenv/vulndemo/lib/python3.10/site-packages/gunicorn/arbiter.py", line 589, in spawn_worker
    worker.init_process()
  File "/home/ubuntu/virtualenv/vulndemo/lib/python3.10/site-packages/gunicorn/workers/ggevent.py", line 146, in init_process
    super().init_process()
  File "/home/ubuntu/virtualenv/vulndemo/lib/python3.10/site-packages/gunicorn/workers/base.py", line 134, in init_process
    self.load_wsgi()
  File "/home/ubuntu/virtualenv/vulndemo/lib/python3.10/site-packages/gunicorn/workers/base.py", line 146, in load_wsgi
    self.wsgi = self.app.wsgi()
  File "/home/ubuntu/virtualenv/vulndemo/lib/python3.10/site-packages/gunicorn/app/base.py", line 67, in wsgi
    self.callable = self.load()
  File "/home/ubuntu/virtualenv/vulndemo/lib/python3.10/site-packages/gunicorn/app/wsgiapp.py", line 58, in load
    return self.load_wsgiapp()
  File "/home/ubuntu/virtualenv/vulndemo/lib/python3.10/site-packages/gunicorn/app/wsgiapp.py", line 48, in load_wsgiapp
    return util.import_app(self.app_uri)
  File "/home/ubuntu/virtualenv/vulndemo/lib/python3.10/site-packages/gunicorn/util.py", line 359, in import_app
    mod = importlib.import_module(module)
  File "/usr/lib/python3.10/importlib/__init__.py", line 126, in import_module
    return _bootstrap._gcd_import(name[level:], package, level)
  File "<frozen importlib._bootstrap>", line 1050, in _gcd_import
  File "<frozen importlib._bootstrap>", line 1027, in _find_and_load
  File "<frozen importlib._bootstrap>", line 1006, in _find_and_load_unlocked
  File "<frozen importlib._bootstrap>", line 688, in _load_unlocked
  File "<frozen importlib._bootstrap_external>", line 883, in exec_module
  File "<frozen importlib._bootstrap>", line 241, in _call_with_frames_removed
  File "/home/ubuntu/work/app.py", line 7, in <module>
    from flask_cors import CORS, cross_origin
ModuleNotFoundError: No module named 'flask_cors'
[2022-12-02 15:40:05 +0800] [815402] [INFO] Worker exiting (pid: 815402)
Traceback (most recent call last):
  File "src/gevent/greenlet.py", line 908, in gevent._gevent_cgreenlet.Greenlet.run
  File "/home/ubuntu/virtualenv/vulndemo/lib/python3.10/site-packages/gunicorn/arbiter.py", line 242, in handle_chld
    self.reap_workers()
  File "/home/ubuntu/virtualenv/vulndemo/lib/python3.10/site-packages/gunicorn/arbiter.py", line 525, in reap_workers
    raise HaltServer(reason, self.WORKER_BOOT_ERROR)
gunicorn.errors.HaltServer: <HaltServer 'Worker failed to boot.' 3>
2022-12-02T07:40:05Z <Greenlet at 0x7f2343a9a700: <bound method Arbiter.handle_chld of <gunicorn.arbiter.Arbiter object at 0x7f2343a79f90>>(17, None)> failed with HaltServer

Traceback (most recent call last):
  File "src/gevent/greenlet.py", line 908, in gevent._gevent_cgreenlet.Greenlet.run
  File "/home/ubuntu/virtualenv/vulndemo/lib/python3.10/site-packages/gunicorn/arbiter.py", line 242, in handle_chld
    self.reap_workers()
  File "/home/ubuntu/virtualenv/vulndemo/lib/python3.10/site-packages/gunicorn/arbiter.py", line 525, in reap_workers
    raise HaltServer(reason, self.WORKER_BOOT_ERROR)
gunicorn.errors.HaltServer: <HaltServer 'Worker failed to boot.' 3>
2022-12-02T07:40:05Z <Greenlet at 0x7f2343a9a700: <bound method Arbiter.handle_chld of <gunicorn.arbiter.Arbiter object at 0x7f2343a79f90>>(17, None)> failed with HaltServer

Traceback (most recent call last):
  File "src/gevent/greenlet.py", line 908, in gevent._gevent_cgreenlet.Greenlet.run
  File "/home/ubuntu/virtualenv/vulndemo/lib/python3.10/site-packages/gunicorn/arbiter.py", line 242, in handle_chld
    self.reap_workers()
  File "/home/ubuntu/virtualenv/vulndemo/lib/python3.10/site-packages/gunicorn/arbiter.py", line 525, in reap_workers
    raise HaltServer(reason, self.WORKER_BOOT_ERROR)
gunicorn.errors.HaltServer: <HaltServer 'Worker failed to boot.' 3>
2022-12-02T07:40:05Z <Greenlet at 0x7f2343a9a700: <bound method Arbiter.handle_chld of <gunicorn.arbiter.Arbiter object at 0x7f2343a79f90>>(17, None)> failed with HaltServer

[2022-12-02 15:40:35 +0800] [815296] [CRITICAL] WORKER TIMEOUT (pid:815398)
[2022-12-02 15:40:35 +0800] [815296] [CRITICAL] WORKER TIMEOUT (pid:815399)
[2022-12-02 15:40:35 +0800] [815296] [CRITICAL] WORKER TIMEOUT (pid:815401)
[2022-12-02 15:40:35 +0800] [815296] [CRITICAL] WORKER TIMEOUT (pid:815402)
[2022-12-02 15:40:35 +0800] [815469] [INFO] Booting worker with pid: 815469
[2022-12-02 15:40:35 +0800] [815470] [INFO] Booting worker with pid: 815470
[2022-12-02 15:40:35 +0800] [815471] [INFO] Booting worker with pid: 815471
[2022-12-02 15:40:35 +0800] [815472] [INFO] Booting worker with pid: 815472
[2022-12-02 15:40:35 +0800] [815469] [ERROR] Exception in worker process
Traceback (most recent call last):
  File "/home/ubuntu/virtualenv/vulndemo/lib/python3.10/site-packages/gunicorn/arbiter.py", line 589, in spawn_worker
    worker.init_process()
  File "/home/ubuntu/virtualenv/vulndemo/lib/python3.10/site-packages/gunicorn/workers/ggevent.py", line 146, in init_process
    super().init_process()
  File "/home/ubuntu/virtualenv/vulndemo/lib/python3.10/site-packages/gunicorn/workers/base.py", line 134, in init_process
    self.load_wsgi()
  File "/home/ubuntu/virtualenv/vulndemo/lib/python3.10/site-packages/gunicorn/workers/base.py", line 146, in load_wsgi
    self.wsgi = self.app.wsgi()
  File "/home/ubuntu/virtualenv/vulndemo/lib/python3.10/site-packages/gunicorn/app/base.py", line 67, in wsgi
    self.callable = self.load()
  File "/home/ubuntu/virtualenv/vulndemo/lib/python3.10/site-packages/gunicorn/app/wsgiapp.py", line 58, in load
    return self.load_wsgiapp()
  File "/home/ubuntu/virtualenv/vulndemo/lib/python3.10/site-packages/gunicorn/app/wsgiapp.py", line 48, in load_wsgiapp
    return util.import_app(self.app_uri)
  File "/home/ubuntu/virtualenv/vulndemo/lib/python3.10/site-packages/gunicorn/util.py", line 359, in import_app
    mod = importlib.import_module(module)
  File "/usr/lib/python3.10/importlib/__init__.py", line 126, in import_module
    return _bootstrap._gcd_import(name[level:], package, level)
  File "<frozen importlib._bootstrap>", line 1050, in _gcd_import
  File "<frozen importlib._bootstrap>", line 1027, in _find_and_load
  File "<frozen importlib._bootstrap>", line 1006, in _find_and_load_unlocked
  File "<frozen importlib._bootstrap>", line 688, in _load_unlocked
  File "<frozen importlib._bootstrap_external>", line 883, in exec_module
  File "<frozen importlib._bootstrap>", line 241, in _call_with_frames_removed
  File "/home/ubuntu/work/app.py", line 7, in <module>
    from flask_cors import CORS, cross_origin
ModuleNotFoundError: No module named 'flask_cors'
[2022-12-02 15:40:35 +0800] [815469] [INFO] Worker exiting (pid: 815469)
[2022-12-02 15:40:35 +0800] [815470] [ERROR] Exception in worker process
Traceback (most recent call last):
  File "/home/ubuntu/virtualenv/vulndemo/lib/python3.10/site-packages/gunicorn/arbiter.py", line 589, in spawn_worker
    worker.init_process()
  File "/home/ubuntu/virtualenv/vulndemo/lib/python3.10/site-packages/gunicorn/workers/ggevent.py", line 146, in init_process
    super().init_process()
  File "/home/ubuntu/virtualenv/vulndemo/lib/python3.10/site-packages/gunicorn/workers/base.py", line 134, in init_process
    self.load_wsgi()
  File "/home/ubuntu/virtualenv/vulndemo/lib/python3.10/site-packages/gunicorn/workers/base.py", line 146, in load_wsgi
    self.wsgi = self.app.wsgi()
  File "/home/ubuntu/virtualenv/vulndemo/lib/python3.10/site-packages/gunicorn/app/base.py", line 67, in wsgi
    self.callable = self.load()
  File "/home/ubuntu/virtualenv/vulndemo/lib/python3.10/site-packages/gunicorn/app/wsgiapp.py", line 58, in load
    return self.load_wsgiapp()
  File "/home/ubuntu/virtualenv/vulndemo/lib/python3.10/site-packages/gunicorn/app/wsgiapp.py", line 48, in load_wsgiapp
    return util.import_app(self.app_uri)
  File "/home/ubuntu/virtualenv/vulndemo/lib/python3.10/site-packages/gunicorn/util.py", line 359, in import_app
    mod = importlib.import_module(module)
  File "/usr/lib/python3.10/importlib/__init__.py", line 126, in import_module
    return _bootstrap._gcd_import(name[level:], package, level)
  File "<frozen importlib._bootstrap>", line 1050, in _gcd_import
  File "<frozen importlib._bootstrap>", line 1027, in _find_and_load
  File "<frozen importlib._bootstrap>", line 1006, in _find_and_load_unlocked
  File "<frozen importlib._bootstrap>", line 688, in _load_unlocked
  File "<frozen importlib._bootstrap_external>", line 883, in exec_module
  File "<frozen importlib._bootstrap>", line 241, in _call_with_frames_removed
  File "/home/ubuntu/work/app.py", line 7, in <module>
    from flask_cors import CORS, cross_origin
ModuleNotFoundError: No module named 'flask_cors'
[2022-12-02 15:40:35 +0800] [815470] [INFO] Worker exiting (pid: 815470)
Traceback (most recent call last):
  File "src/gevent/greenlet.py", line 908, in gevent._gevent_cgreenlet.Greenlet.run
  File "/home/ubuntu/virtualenv/vulndemo/lib/python3.10/site-packages/gunicorn/arbiter.py", line 242, in handle_chld
    self.reap_workers()
  File "/home/ubuntu/virtualenv/vulndemo/lib/python3.10/site-packages/gunicorn/arbiter.py", line 525, in reap_workers
    raise HaltServer(reason, self.WORKER_BOOT_ERROR)
gunicorn.errors.HaltServer: <HaltServer 'Worker failed to boot.' 3>
2022-12-02T07:40:35Z <Greenlet at 0x7f2343a9a700: <bound method Arbiter.handle_chld of <gunicorn.arbiter.Arbiter object at 0x7f2343a79f90>>(17, None)> failed with HaltServer

[2022-12-02 15:40:35 +0800] [815471] [ERROR] Exception in worker process
Traceback (most recent call last):
  File "/home/ubuntu/virtualenv/vulndemo/lib/python3.10/site-packages/gunicorn/arbiter.py", line 589, in spawn_worker
    worker.init_process()
  File "/home/ubuntu/virtualenv/vulndemo/lib/python3.10/site-packages/gunicorn/workers/ggevent.py", line 146, in init_process
    super().init_process()
  File "/home/ubuntu/virtualenv/vulndemo/lib/python3.10/site-packages/gunicorn/workers/base.py", line 134, in init_process
    self.load_wsgi()
  File "/home/ubuntu/virtualenv/vulndemo/lib/python3.10/site-packages/gunicorn/workers/base.py", line 146, in load_wsgi
    self.wsgi = self.app.wsgi()
  File "/home/ubuntu/virtualenv/vulndemo/lib/python3.10/site-packages/gunicorn/app/base.py", line 67, in wsgi
    self.callable = self.load()
  File "/home/ubuntu/virtualenv/vulndemo/lib/python3.10/site-packages/gunicorn/app/wsgiapp.py", line 58, in load
    return self.load_wsgiapp()
  File "/home/ubuntu/virtualenv/vulndemo/lib/python3.10/site-packages/gunicorn/app/wsgiapp.py", line 48, in load_wsgiapp
    return util.import_app(self.app_uri)
  File "/home/ubuntu/virtualenv/vulndemo/lib/python3.10/site-packages/gunicorn/util.py", line 359, in import_app
    mod = importlib.import_module(module)
  File "/usr/lib/python3.10/importlib/__init__.py", line 126, in import_module
    return _bootstrap._gcd_import(name[level:], package, level)
  File "<frozen importlib._bootstrap>", line 1050, in _gcd_import
  File "<frozen importlib._bootstrap>", line 1027, in _find_and_load
  File "<frozen importlib._bootstrap>", line 1006, in _find_and_load_unlocked
  File "<frozen importlib._bootstrap>", line 688, in _load_unlocked
  File "<frozen importlib._bootstrap_external>", line 883, in exec_module
  File "<frozen importlib._bootstrap>", line 241, in _call_with_frames_removed
  File "/home/ubuntu/work/app.py", line 7, in <module>
    from flask_cors import CORS, cross_origin
ModuleNotFoundError: No module named 'flask_cors'
[2022-12-02 15:40:35 +0800] [815471] [INFO] Worker exiting (pid: 815471)
[2022-12-02 15:40:35 +0800] [815472] [ERROR] Exception in worker process
Traceback (most recent call last):
  File "/home/ubuntu/virtualenv/vulndemo/lib/python3.10/site-packages/gunicorn/arbiter.py", line 589, in spawn_worker
    worker.init_process()
  File "/home/ubuntu/virtualenv/vulndemo/lib/python3.10/site-packages/gunicorn/workers/ggevent.py", line 146, in init_process
    super().init_process()
  File "/home/ubuntu/virtualenv/vulndemo/lib/python3.10/site-packages/gunicorn/workers/base.py", line 134, in init_process
    self.load_wsgi()
  File "/home/ubuntu/virtualenv/vulndemo/lib/python3.10/site-packages/gunicorn/workers/base.py", line 146, in load_wsgi
    self.wsgi = self.app.wsgi()
  File "/home/ubuntu/virtualenv/vulndemo/lib/python3.10/site-packages/gunicorn/app/base.py", line 67, in wsgi
    self.callable = self.load()
  File "/home/ubuntu/virtualenv/vulndemo/lib/python3.10/site-packages/gunicorn/app/wsgiapp.py", line 58, in load
    return self.load_wsgiapp()
  File "/home/ubuntu/virtualenv/vulndemo/lib/python3.10/site-packages/gunicorn/app/wsgiapp.py", line 48, in load_wsgiapp
    return util.import_app(self.app_uri)
  File "/home/ubuntu/virtualenv/vulndemo/lib/python3.10/site-packages/gunicorn/util.py", line 359, in import_app
    mod = importlib.import_module(module)
  File "/usr/lib/python3.10/importlib/__init__.py", line 126, in import_module
    return _bootstrap._gcd_import(name[level:], package, level)
  File "<frozen importlib._bootstrap>", line 1050, in _gcd_import
  File "<frozen importlib._bootstrap>", line 1027, in _find_and_load
  File "<frozen importlib._bootstrap>", line 1006, in _find_and_load_unlocked
  File "<frozen importlib._bootstrap>", line 688, in _load_unlocked
  File "<frozen importlib._bootstrap_external>", line 883, in exec_module
  File "<frozen importlib._bootstrap>", line 241, in _call_with_frames_removed
  File "/home/ubuntu/work/app.py", line 7, in <module>
    from flask_cors import CORS, cross_origin
ModuleNotFoundError: No module named 'flask_cors'
[2022-12-02 15:40:35 +0800] [815472] [INFO] Worker exiting (pid: 815472)
Traceback (most recent call last):
  File "src/gevent/greenlet.py", line 908, in gevent._gevent_cgreenlet.Greenlet.run
  File "/home/ubuntu/virtualenv/vulndemo/lib/python3.10/site-packages/gunicorn/arbiter.py", line 242, in handle_chld
    self.reap_workers()
  File "/home/ubuntu/virtualenv/vulndemo/lib/python3.10/site-packages/gunicorn/arbiter.py", line 525, in reap_workers
    raise HaltServer(reason, self.WORKER_BOOT_ERROR)
gunicorn.errors.HaltServer: <HaltServer 'Worker failed to boot.' 3>
2022-12-02T07:40:35Z <Greenlet at 0x7f2343a9a700: <bound method Arbiter.handle_chld of <gunicorn.arbiter.Arbiter object at 0x7f2343a79f90>>(17, None)> failed with HaltServer

Traceback (most recent call last):
  File "src/gevent/greenlet.py", line 908, in gevent._gevent_cgreenlet.Greenlet.run
  File "/home/ubuntu/virtualenv/vulndemo/lib/python3.10/site-packages/gunicorn/arbiter.py", line 242, in handle_chld
    self.reap_workers()
  File "/home/ubuntu/virtualenv/vulndemo/lib/python3.10/site-packages/gunicorn/arbiter.py", line 525, in reap_workers
    raise HaltServer(reason, self.WORKER_BOOT_ERROR)
gunicorn.errors.HaltServer: <HaltServer 'Worker failed to boot.' 3>
2022-12-02T07:40:35Z <Greenlet at 0x7f2343a9a700: <bound method Arbiter.handle_chld of <gunicorn.arbiter.Arbiter object at 0x7f2343a79f90>>(17, None)> failed with HaltServer

Traceback (most recent call last):
  File "src/gevent/greenlet.py", line 908, in gevent._gevent_cgreenlet.Greenlet.run
  File "/home/ubuntu/virtualenv/vulndemo/lib/python3.10/site-packages/gunicorn/arbiter.py", line 242, in handle_chld
    self.reap_workers()
  File "/home/ubuntu/virtualenv/vulndemo/lib/python3.10/site-packages/gunicorn/arbiter.py", line 525, in reap_workers
    raise HaltServer(reason, self.WORKER_BOOT_ERROR)
gunicorn.errors.HaltServer: <HaltServer 'Worker failed to boot.' 3>
2022-12-02T07:40:35Z <Greenlet at 0x7f2343a9a700: <bound method Arbiter.handle_chld of <gunicorn.arbiter.Arbiter object at 0x7f2343a79f90>>(17, None)> failed with HaltServer

[2022-12-02 15:41:05 +0800] [815296] [CRITICAL] WORKER TIMEOUT (pid:815469)
[2022-12-02 15:41:05 +0800] [815296] [CRITICAL] WORKER TIMEOUT (pid:815470)
[2022-12-02 15:41:05 +0800] [815296] [CRITICAL] WORKER TIMEOUT (pid:815471)
[2022-12-02 15:41:05 +0800] [815296] [CRITICAL] WORKER TIMEOUT (pid:815472)
[2022-12-02 15:41:05 +0800] [815592] [INFO] Booting worker with pid: 815592
[2022-12-02 15:41:05 +0800] [815593] [INFO] Booting worker with pid: 815593
[2022-12-02 15:41:05 +0800] [815595] [INFO] Booting worker with pid: 815595
[2022-12-02 15:41:05 +0800] [815592] [ERROR] Exception in worker process
Traceback (most recent call last):
  File "/home/ubuntu/virtualenv/vulndemo/lib/python3.10/site-packages/gunicorn/arbiter.py", line 589, in spawn_worker
    worker.init_process()
  File "/home/ubuntu/virtualenv/vulndemo/lib/python3.10/site-packages/gunicorn/workers/ggevent.py", line 146, in init_process
    super().init_process()
  File "/home/ubuntu/virtualenv/vulndemo/lib/python3.10/site-packages/gunicorn/workers/base.py", line 134, in init_process
    self.load_wsgi()
  File "/home/ubuntu/virtualenv/vulndemo/lib/python3.10/site-packages/gunicorn/workers/base.py", line 146, in load_wsgi
    self.wsgi = self.app.wsgi()
  File "/home/ubuntu/virtualenv/vulndemo/lib/python3.10/site-packages/gunicorn/app/base.py", line 67, in wsgi
    self.callable = self.load()
  File "/home/ubuntu/virtualenv/vulndemo/lib/python3.10/site-packages/gunicorn/app/wsgiapp.py", line 58, in load
    return self.load_wsgiapp()
  File "/home/ubuntu/virtualenv/vulndemo/lib/python3.10/site-packages/gunicorn/app/wsgiapp.py", line 48, in load_wsgiapp
    return util.import_app(self.app_uri)
  File "/home/ubuntu/virtualenv/vulndemo/lib/python3.10/site-packages/gunicorn/util.py", line 359, in import_app
    mod = importlib.import_module(module)
  File "/usr/lib/python3.10/importlib/__init__.py", line 126, in import_module
    return _bootstrap._gcd_import(name[level:], package, level)
  File "<frozen importlib._bootstrap>", line 1050, in _gcd_import
  File "<frozen importlib._bootstrap>", line 1027, in _find_and_load
  File "<frozen importlib._bootstrap>", line 1006, in _find_and_load_unlocked
  File "<frozen importlib._bootstrap>", line 688, in _load_unlocked
  File "<frozen importlib._bootstrap_external>", line 883, in exec_module
  File "<frozen importlib._bootstrap>", line 241, in _call_with_frames_removed
  File "/home/ubuntu/work/app.py", line 7, in <module>
    from flask_cors import CORS, cross_origin
ModuleNotFoundError: No module named 'flask_cors'
[2022-12-02 15:41:05 +0800] [815592] [INFO] Worker exiting (pid: 815592)
[2022-12-02 15:41:05 +0800] [815596] [INFO] Booting worker with pid: 815596
Traceback (most recent call last):
  File "src/gevent/greenlet.py", line 908, in gevent._gevent_cgreenlet.Greenlet.run
  File "/home/ubuntu/virtualenv/vulndemo/lib/python3.10/site-packages/gunicorn/arbiter.py", line 242, in handle_chld
    self.reap_workers()
  File "/home/ubuntu/virtualenv/vulndemo/lib/python3.10/site-packages/gunicorn/arbiter.py", line 525, in reap_workers
    raise HaltServer(reason, self.WORKER_BOOT_ERROR)
gunicorn.errors.HaltServer: <HaltServer 'Worker failed to boot.' 3>
2022-12-02T07:41:05Z <Greenlet at 0x7f2343a9a700: <bound method Arbiter.handle_chld of <gunicorn.arbiter.Arbiter object at 0x7f2343a79f90>>(17, None)> failed with HaltServer

[2022-12-02 15:41:05 +0800] [815593] [ERROR] Exception in worker process
Traceback (most recent call last):
  File "/home/ubuntu/virtualenv/vulndemo/lib/python3.10/site-packages/gunicorn/arbiter.py", line 589, in spawn_worker
    worker.init_process()
  File "/home/ubuntu/virtualenv/vulndemo/lib/python3.10/site-packages/gunicorn/workers/ggevent.py", line 146, in init_process
    super().init_process()
  File "/home/ubuntu/virtualenv/vulndemo/lib/python3.10/site-packages/gunicorn/workers/base.py", line 134, in init_process
    self.load_wsgi()
  File "/home/ubuntu/virtualenv/vulndemo/lib/python3.10/site-packages/gunicorn/workers/base.py", line 146, in load_wsgi
    self.wsgi = self.app.wsgi()
  File "/home/ubuntu/virtualenv/vulndemo/lib/python3.10/site-packages/gunicorn/app/base.py", line 67, in wsgi
    self.callable = self.load()
  File "/home/ubuntu/virtualenv/vulndemo/lib/python3.10/site-packages/gunicorn/app/wsgiapp.py", line 58, in load
    return self.load_wsgiapp()
  File "/home/ubuntu/virtualenv/vulndemo/lib/python3.10/site-packages/gunicorn/app/wsgiapp.py", line 48, in load_wsgiapp
    return util.import_app(self.app_uri)
  File "/home/ubuntu/virtualenv/vulndemo/lib/python3.10/site-packages/gunicorn/util.py", line 359, in import_app
    mod = importlib.import_module(module)
  File "/usr/lib/python3.10/importlib/__init__.py", line 126, in import_module
    return _bootstrap._gcd_import(name[level:], package, level)
  File "<frozen importlib._bootstrap>", line 1050, in _gcd_import
  File "<frozen importlib._bootstrap>", line 1027, in _find_and_load
  File "<frozen importlib._bootstrap>", line 1006, in _find_and_load_unlocked
  File "<frozen importlib._bootstrap>", line 688, in _load_unlocked
  File "<frozen importlib._bootstrap_external>", line 883, in exec_module
  File "<frozen importlib._bootstrap>", line 241, in _call_with_frames_removed
  File "/home/ubuntu/work/app.py", line 7, in <module>
    from flask_cors import CORS, cross_origin
ModuleNotFoundError: No module named 'flask_cors'
[2022-12-02 15:41:05 +0800] [815593] [INFO] Worker exiting (pid: 815593)
[2022-12-02 15:41:05 +0800] [815595] [ERROR] Exception in worker process
Traceback (most recent call last):
  File "/home/ubuntu/virtualenv/vulndemo/lib/python3.10/site-packages/gunicorn/arbiter.py", line 589, in spawn_worker
    worker.init_process()
  File "/home/ubuntu/virtualenv/vulndemo/lib/python3.10/site-packages/gunicorn/workers/ggevent.py", line 146, in init_process
    super().init_process()
  File "/home/ubuntu/virtualenv/vulndemo/lib/python3.10/site-packages/gunicorn/workers/base.py", line 134, in init_process
    self.load_wsgi()
  File "/home/ubuntu/virtualenv/vulndemo/lib/python3.10/site-packages/gunicorn/workers/base.py", line 146, in load_wsgi
    self.wsgi = self.app.wsgi()
  File "/home/ubuntu/virtualenv/vulndemo/lib/python3.10/site-packages/gunicorn/app/base.py", line 67, in wsgi
    self.callable = self.load()
  File "/home/ubuntu/virtualenv/vulndemo/lib/python3.10/site-packages/gunicorn/app/wsgiapp.py", line 58, in load
    return self.load_wsgiapp()
  File "/home/ubuntu/virtualenv/vulndemo/lib/python3.10/site-packages/gunicorn/app/wsgiapp.py", line 48, in load_wsgiapp
    return util.import_app(self.app_uri)
  File "/home/ubuntu/virtualenv/vulndemo/lib/python3.10/site-packages/gunicorn/util.py", line 359, in import_app
    mod = importlib.import_module(module)
  File "/usr/lib/python3.10/importlib/__init__.py", line 126, in import_module
    return _bootstrap._gcd_import(name[level:], package, level)
  File "<frozen importlib._bootstrap>", line 1050, in _gcd_import
  File "<frozen importlib._bootstrap>", line 1027, in _find_and_load
  File "<frozen importlib._bootstrap>", line 1006, in _find_and_load_unlocked
  File "<frozen importlib._bootstrap>", line 688, in _load_unlocked
  File "<frozen importlib._bootstrap_external>", line 883, in exec_module
  File "<frozen importlib._bootstrap>", line 241, in _call_with_frames_removed
  File "/home/ubuntu/work/app.py", line 7, in <module>
    from flask_cors import CORS, cross_origin
ModuleNotFoundError: No module named 'flask_cors'
[2022-12-02 15:41:05 +0800] [815595] [INFO] Worker exiting (pid: 815595)
Traceback (most recent call last):
  File "src/gevent/greenlet.py", line 908, in gevent._gevent_cgreenlet.Greenlet.run
  File "/home/ubuntu/virtualenv/vulndemo/lib/python3.10/site-packages/gunicorn/arbiter.py", line 242, in handle_chld
    self.reap_workers()
  File "/home/ubuntu/virtualenv/vulndemo/lib/python3.10/site-packages/gunicorn/arbiter.py", line 525, in reap_workers
    raise HaltServer(reason, self.WORKER_BOOT_ERROR)
gunicorn.errors.HaltServer: <HaltServer 'Worker failed to boot.' 3>
2022-12-02T07:41:06Z <Greenlet at 0x7f2343a9a700: <bound method Arbiter.handle_chld of <gunicorn.arbiter.Arbiter object at 0x7f2343a79f90>>(17, None)> failed with HaltServer

[2022-12-02 15:41:06 +0800] [815596] [ERROR] Exception in worker process
Traceback (most recent call last):
  File "/home/ubuntu/virtualenv/vulndemo/lib/python3.10/site-packages/gunicorn/arbiter.py", line 589, in spawn_worker
    worker.init_process()
  File "/home/ubuntu/virtualenv/vulndemo/lib/python3.10/site-packages/gunicorn/workers/ggevent.py", line 146, in init_process
    super().init_process()
  File "/home/ubuntu/virtualenv/vulndemo/lib/python3.10/site-packages/gunicorn/workers/base.py", line 134, in init_process
    self.load_wsgi()
  File "/home/ubuntu/virtualenv/vulndemo/lib/python3.10/site-packages/gunicorn/workers/base.py", line 146, in load_wsgi
    self.wsgi = self.app.wsgi()
  File "/home/ubuntu/virtualenv/vulndemo/lib/python3.10/site-packages/gunicorn/app/base.py", line 67, in wsgi
    self.callable = self.load()
  File "/home/ubuntu/virtualenv/vulndemo/lib/python3.10/site-packages/gunicorn/app/wsgiapp.py", line 58, in load
    return self.load_wsgiapp()
  File "/home/ubuntu/virtualenv/vulndemo/lib/python3.10/site-packages/gunicorn/app/wsgiapp.py", line 48, in load_wsgiapp
    return util.import_app(self.app_uri)
  File "/home/ubuntu/virtualenv/vulndemo/lib/python3.10/site-packages/gunicorn/util.py", line 359, in import_app
    mod = importlib.import_module(module)
  File "/usr/lib/python3.10/importlib/__init__.py", line 126, in import_module
    return _bootstrap._gcd_import(name[level:], package, level)
  File "<frozen importlib._bootstrap>", line 1050, in _gcd_import
  File "<frozen importlib._bootstrap>", line 1027, in _find_and_load
  File "<frozen importlib._bootstrap>", line 1006, in _find_and_load_unlocked
  File "<frozen importlib._bootstrap>", line 688, in _load_unlocked
  File "<frozen importlib._bootstrap_external>", line 883, in exec_module
  File "<frozen importlib._bootstrap>", line 241, in _call_with_frames_removed
  File "/home/ubuntu/work/app.py", line 7, in <module>
    from flask_cors import CORS, cross_origin
ModuleNotFoundError: No module named 'flask_cors'
[2022-12-02 15:41:06 +0800] [815596] [INFO] Worker exiting (pid: 815596)
Traceback (most recent call last):
  File "src/gevent/greenlet.py", line 908, in gevent._gevent_cgreenlet.Greenlet.run
  File "/home/ubuntu/virtualenv/vulndemo/lib/python3.10/site-packages/gunicorn/arbiter.py", line 242, in handle_chld
    self.reap_workers()
  File "/home/ubuntu/virtualenv/vulndemo/lib/python3.10/site-packages/gunicorn/arbiter.py", line 525, in reap_workers
    raise HaltServer(reason, self.WORKER_BOOT_ERROR)
gunicorn.errors.HaltServer: <HaltServer 'Worker failed to boot.' 3>
2022-12-02T07:41:06Z <Greenlet at 0x7f2343a9a700: <bound method Arbiter.handle_chld of <gunicorn.arbiter.Arbiter object at 0x7f2343a79f90>>(17, None)> failed with HaltServer

Traceback (most recent call last):
  File "src/gevent/greenlet.py", line 908, in gevent._gevent_cgreenlet.Greenlet.run
  File "/home/ubuntu/virtualenv/vulndemo/lib/python3.10/site-packages/gunicorn/arbiter.py", line 242, in handle_chld
    self.reap_workers()
  File "/home/ubuntu/virtualenv/vulndemo/lib/python3.10/site-packages/gunicorn/arbiter.py", line 525, in reap_workers
    raise HaltServer(reason, self.WORKER_BOOT_ERROR)
gunicorn.errors.HaltServer: <HaltServer 'Worker failed to boot.' 3>
2022-12-02T07:41:06Z <Greenlet at 0x7f2343a9a700: <bound method Arbiter.handle_chld of <gunicorn.arbiter.Arbiter object at 0x7f2343a79f90>>(17, None)> failed with HaltServer

[2022-12-02 15:41:35 +0800] [815296] [CRITICAL] WORKER TIMEOUT (pid:815592)
[2022-12-02 15:41:35 +0800] [815296] [CRITICAL] WORKER TIMEOUT (pid:815593)
[2022-12-02 15:41:35 +0800] [815296] [CRITICAL] WORKER TIMEOUT (pid:815595)
[2022-12-02 15:41:35 +0800] [815296] [CRITICAL] WORKER TIMEOUT (pid:815596)
[2022-12-02 15:41:35 +0800] [815672] [INFO] Booting worker with pid: 815672
[2022-12-02 15:41:35 +0800] [815673] [INFO] Booting worker with pid: 815673
[2022-12-02 15:41:35 +0800] [815672] [ERROR] Exception in worker process
Traceback (most recent call last):
  File "/home/ubuntu/virtualenv/vulndemo/lib/python3.10/site-packages/gunicorn/arbiter.py", line 589, in spawn_worker
    worker.init_process()
  File "/home/ubuntu/virtualenv/vulndemo/lib/python3.10/site-packages/gunicorn/workers/ggevent.py", line 146, in init_process
    super().init_process()
  File "/home/ubuntu/virtualenv/vulndemo/lib/python3.10/site-packages/gunicorn/workers/base.py", line 134, in init_process
    self.load_wsgi()
  File "/home/ubuntu/virtualenv/vulndemo/lib/python3.10/site-packages/gunicorn/workers/base.py", line 146, in load_wsgi
    self.wsgi = self.app.wsgi()
  File "/home/ubuntu/virtualenv/vulndemo/lib/python3.10/site-packages/gunicorn/app/base.py", line 67, in wsgi
    self.callable = self.load()
  File "/home/ubuntu/virtualenv/vulndemo/lib/python3.10/site-packages/gunicorn/app/wsgiapp.py", line 58, in load
    return self.load_wsgiapp()
  File "/home/ubuntu/virtualenv/vulndemo/lib/python3.10/site-packages/gunicorn/app/wsgiapp.py", line 48, in load_wsgiapp
    return util.import_app(self.app_uri)
  File "/home/ubuntu/virtualenv/vulndemo/lib/python3.10/site-packages/gunicorn/util.py", line 359, in import_app
    mod = importlib.import_module(module)
  File "/usr/lib/python3.10/importlib/__init__.py", line 126, in import_module
    return _bootstrap._gcd_import(name[level:], package, level)
  File "<frozen importlib._bootstrap>", line 1050, in _gcd_import
  File "<frozen importlib._bootstrap>", line 1027, in _find_and_load
  File "<frozen importlib._bootstrap>", line 1006, in _find_and_load_unlocked
  File "<frozen importlib._bootstrap>", line 688, in _load_unlocked
  File "<frozen importlib._bootstrap_external>", line 883, in exec_module
  File "<frozen importlib._bootstrap>", line 241, in _call_with_frames_removed
  File "/home/ubuntu/work/app.py", line 7, in <module>
    from flask_cors import CORS, cross_origin
ModuleNotFoundError: No module named 'flask_cors'
[2022-12-02 15:41:35 +0800] [815672] [INFO] Worker exiting (pid: 815672)
[2022-12-02 15:41:35 +0800] [815675] [INFO] Booting worker with pid: 815675
[2022-12-02 15:41:36 +0800] [815682] [INFO] Booting worker with pid: 815682
Traceback (most recent call last):
  File "src/gevent/greenlet.py", line 908, in gevent._gevent_cgreenlet.Greenlet.run
  File "/home/ubuntu/virtualenv/vulndemo/lib/python3.10/site-packages/gunicorn/arbiter.py", line 242, in handle_chld
    self.reap_workers()
  File "/home/ubuntu/virtualenv/vulndemo/lib/python3.10/site-packages/gunicorn/arbiter.py", line 525, in reap_workers
    raise HaltServer(reason, self.WORKER_BOOT_ERROR)
gunicorn.errors.HaltServer: <HaltServer 'Worker failed to boot.' 3>
2022-12-02T07:41:36Z <Greenlet at 0x7f2343a9a700: <bound method Arbiter.handle_chld of <gunicorn.arbiter.Arbiter object at 0x7f2343a79f90>>(17, None)> failed with HaltServer

[2022-12-02 15:41:36 +0800] [815673] [ERROR] Exception in worker process
Traceback (most recent call last):
  File "/home/ubuntu/virtualenv/vulndemo/lib/python3.10/site-packages/gunicorn/arbiter.py", line 589, in spawn_worker
    worker.init_process()
  File "/home/ubuntu/virtualenv/vulndemo/lib/python3.10/site-packages/gunicorn/workers/ggevent.py", line 146, in init_process
    super().init_process()
  File "/home/ubuntu/virtualenv/vulndemo/lib/python3.10/site-packages/gunicorn/workers/base.py", line 134, in init_process
    self.load_wsgi()
  File "/home/ubuntu/virtualenv/vulndemo/lib/python3.10/site-packages/gunicorn/workers/base.py", line 146, in load_wsgi
    self.wsgi = self.app.wsgi()
  File "/home/ubuntu/virtualenv/vulndemo/lib/python3.10/site-packages/gunicorn/app/base.py", line 67, in wsgi
    self.callable = self.load()
  File "/home/ubuntu/virtualenv/vulndemo/lib/python3.10/site-packages/gunicorn/app/wsgiapp.py", line 58, in load
    return self.load_wsgiapp()
  File "/home/ubuntu/virtualenv/vulndemo/lib/python3.10/site-packages/gunicorn/app/wsgiapp.py", line 48, in load_wsgiapp
    return util.import_app(self.app_uri)
  File "/home/ubuntu/virtualenv/vulndemo/lib/python3.10/site-packages/gunicorn/util.py", line 359, in import_app
    mod = importlib.import_module(module)
  File "/usr/lib/python3.10/importlib/__init__.py", line 126, in import_module
    return _bootstrap._gcd_import(name[level:], package, level)
  File "<frozen importlib._bootstrap>", line 1050, in _gcd_import
  File "<frozen importlib._bootstrap>", line 1027, in _find_and_load
  File "<frozen importlib._bootstrap>", line 1006, in _find_and_load_unlocked
  File "<frozen importlib._bootstrap>", line 688, in _load_unlocked
  File "<frozen importlib._bootstrap_external>", line 883, in exec_module
  File "<frozen importlib._bootstrap>", line 241, in _call_with_frames_removed
  File "/home/ubuntu/work/app.py", line 7, in <module>
    from flask_cors import CORS, cross_origin
ModuleNotFoundError: No module named 'flask_cors'
[2022-12-02 15:41:36 +0800] [815673] [INFO] Worker exiting (pid: 815673)
Traceback (most recent call last):
  File "src/gevent/greenlet.py", line 908, in gevent._gevent_cgreenlet.Greenlet.run
  File "/home/ubuntu/virtualenv/vulndemo/lib/python3.10/site-packages/gunicorn/arbiter.py", line 242, in handle_chld
    self.reap_workers()
  File "/home/ubuntu/virtualenv/vulndemo/lib/python3.10/site-packages/gunicorn/arbiter.py", line 525, in reap_workers
    raise HaltServer(reason, self.WORKER_BOOT_ERROR)
gunicorn.errors.HaltServer: <HaltServer 'Worker failed to boot.' 3>
2022-12-02T07:41:36Z <Greenlet at 0x7f2343a9a700: <bound method Arbiter.handle_chld of <gunicorn.arbiter.Arbiter object at 0x7f2343a79f90>>(17, None)> failed with HaltServer

[2022-12-02 15:41:36 +0800] [815675] [ERROR] Exception in worker process
Traceback (most recent call last):
  File "/home/ubuntu/virtualenv/vulndemo/lib/python3.10/site-packages/gunicorn/arbiter.py", line 589, in spawn_worker
    worker.init_process()
  File "/home/ubuntu/virtualenv/vulndemo/lib/python3.10/site-packages/gunicorn/workers/ggevent.py", line 146, in init_process
    super().init_process()
  File "/home/ubuntu/virtualenv/vulndemo/lib/python3.10/site-packages/gunicorn/workers/base.py", line 134, in init_process
    self.load_wsgi()
  File "/home/ubuntu/virtualenv/vulndemo/lib/python3.10/site-packages/gunicorn/workers/base.py", line 146, in load_wsgi
    self.wsgi = self.app.wsgi()
  File "/home/ubuntu/virtualenv/vulndemo/lib/python3.10/site-packages/gunicorn/app/base.py", line 67, in wsgi
    self.callable = self.load()
  File "/home/ubuntu/virtualenv/vulndemo/lib/python3.10/site-packages/gunicorn/app/wsgiapp.py", line 58, in load
    return self.load_wsgiapp()
  File "/home/ubuntu/virtualenv/vulndemo/lib/python3.10/site-packages/gunicorn/app/wsgiapp.py", line 48, in load_wsgiapp
    return util.import_app(self.app_uri)
  File "/home/ubuntu/virtualenv/vulndemo/lib/python3.10/site-packages/gunicorn/util.py", line 359, in import_app
    mod = importlib.import_module(module)
  File "/usr/lib/python3.10/importlib/__init__.py", line 126, in import_module
    return _bootstrap._gcd_import(name[level:], package, level)
  File "<frozen importlib._bootstrap>", line 1050, in _gcd_import
  File "<frozen importlib._bootstrap>", line 1027, in _find_and_load
  File "<frozen importlib._bootstrap>", line 1006, in _find_and_load_unlocked
  File "<frozen importlib._bootstrap>", line 688, in _load_unlocked
  File "<frozen importlib._bootstrap_external>", line 883, in exec_module
  File "<frozen importlib._bootstrap>", line 241, in _call_with_frames_removed
  File "/home/ubuntu/work/app.py", line 7, in <module>
    from flask_cors import CORS, cross_origin
ModuleNotFoundError: No module named 'flask_cors'
[2022-12-02 15:41:36 +0800] [815675] [INFO] Worker exiting (pid: 815675)
[2022-12-02 15:41:36 +0800] [815682] [ERROR] Exception in worker process
Traceback (most recent call last):
  File "/home/ubuntu/virtualenv/vulndemo/lib/python3.10/site-packages/gunicorn/arbiter.py", line 589, in spawn_worker
    worker.init_process()
  File "/home/ubuntu/virtualenv/vulndemo/lib/python3.10/site-packages/gunicorn/workers/ggevent.py", line 146, in init_process
    super().init_process()
  File "/home/ubuntu/virtualenv/vulndemo/lib/python3.10/site-packages/gunicorn/workers/base.py", line 134, in init_process
    self.load_wsgi()
  File "/home/ubuntu/virtualenv/vulndemo/lib/python3.10/site-packages/gunicorn/workers/base.py", line 146, in load_wsgi
    self.wsgi = self.app.wsgi()
  File "/home/ubuntu/virtualenv/vulndemo/lib/python3.10/site-packages/gunicorn/app/base.py", line 67, in wsgi
    self.callable = self.load()
  File "/home/ubuntu/virtualenv/vulndemo/lib/python3.10/site-packages/gunicorn/app/wsgiapp.py", line 58, in load
    return self.load_wsgiapp()
  File "/home/ubuntu/virtualenv/vulndemo/lib/python3.10/site-packages/gunicorn/app/wsgiapp.py", line 48, in load_wsgiapp
    return util.import_app(self.app_uri)
  File "/home/ubuntu/virtualenv/vulndemo/lib/python3.10/site-packages/gunicorn/util.py", line 359, in import_app
    mod = importlib.import_module(module)
  File "/usr/lib/python3.10/importlib/__init__.py", line 126, in import_module
    return _bootstrap._gcd_import(name[level:], package, level)
  File "<frozen importlib._bootstrap>", line 1050, in _gcd_import
  File "<frozen importlib._bootstrap>", line 1027, in _find_and_load
  File "<frozen importlib._bootstrap>", line 1006, in _find_and_load_unlocked
  File "<frozen importlib._bootstrap>", line 688, in _load_unlocked
  File "<frozen importlib._bootstrap_external>", line 883, in exec_module
  File "<frozen importlib._bootstrap>", line 241, in _call_with_frames_removed
  File "/home/ubuntu/work/app.py", line 7, in <module>
    from flask_cors import CORS, cross_origin
ModuleNotFoundError: No module named 'flask_cors'
[2022-12-02 15:41:36 +0800] [815682] [INFO] Worker exiting (pid: 815682)
Traceback (most recent call last):
  File "src/gevent/greenlet.py", line 908, in gevent._gevent_cgreenlet.Greenlet.run
  File "/home/ubuntu/virtualenv/vulndemo/lib/python3.10/site-packages/gunicorn/arbiter.py", line 242, in handle_chld
    self.reap_workers()
  File "/home/ubuntu/virtualenv/vulndemo/lib/python3.10/site-packages/gunicorn/arbiter.py", line 525, in reap_workers
    raise HaltServer(reason, self.WORKER_BOOT_ERROR)
gunicorn.errors.HaltServer: <HaltServer 'Worker failed to boot.' 3>
2022-12-02T07:41:36Z <Greenlet at 0x7f2343a9a700: <bound method Arbiter.handle_chld of <gunicorn.arbiter.Arbiter object at 0x7f2343a79f90>>(17, None)> failed with HaltServer

Traceback (most recent call last):
  File "src/gevent/greenlet.py", line 908, in gevent._gevent_cgreenlet.Greenlet.run
  File "/home/ubuntu/virtualenv/vulndemo/lib/python3.10/site-packages/gunicorn/arbiter.py", line 242, in handle_chld
    self.reap_workers()
  File "/home/ubuntu/virtualenv/vulndemo/lib/python3.10/site-packages/gunicorn/arbiter.py", line 525, in reap_workers
    raise HaltServer(reason, self.WORKER_BOOT_ERROR)
gunicorn.errors.HaltServer: <HaltServer 'Worker failed to boot.' 3>
2022-12-02T07:41:36Z <Greenlet at 0x7f2343a9a700: <bound method Arbiter.handle_chld of <gunicorn.arbiter.Arbiter object at 0x7f2343a79f90>>(17, None)> failed with HaltServer

[2022-12-02 15:42:06 +0800] [815296] [CRITICAL] WORKER TIMEOUT (pid:815672)
[2022-12-02 15:42:06 +0800] [815296] [CRITICAL] WORKER TIMEOUT (pid:815673)
[2022-12-02 15:42:06 +0800] [815296] [CRITICAL] WORKER TIMEOUT (pid:815675)
[2022-12-02 15:42:06 +0800] [815296] [CRITICAL] WORKER TIMEOUT (pid:815682)
[2022-12-02 15:42:06 +0800] [815768] [INFO] Booting worker with pid: 815768
[2022-12-02 15:42:06 +0800] [815769] [INFO] Booting worker with pid: 815769
[2022-12-02 15:42:06 +0800] [815770] [INFO] Booting worker with pid: 815770
[2022-12-02 15:42:06 +0800] [815771] [INFO] Booting worker with pid: 815771
[2022-12-02 15:42:06 +0800] [815768] [ERROR] Exception in worker process
Traceback (most recent call last):
  File "/home/ubuntu/virtualenv/vulndemo/lib/python3.10/site-packages/gunicorn/arbiter.py", line 589, in spawn_worker
    worker.init_process()
  File "/home/ubuntu/virtualenv/vulndemo/lib/python3.10/site-packages/gunicorn/workers/ggevent.py", line 146, in init_process
    super().init_process()
  File "/home/ubuntu/virtualenv/vulndemo/lib/python3.10/site-packages/gunicorn/workers/base.py", line 134, in init_process
    self.load_wsgi()
  File "/home/ubuntu/virtualenv/vulndemo/lib/python3.10/site-packages/gunicorn/workers/base.py", line 146, in load_wsgi
    self.wsgi = self.app.wsgi()
  File "/home/ubuntu/virtualenv/vulndemo/lib/python3.10/site-packages/gunicorn/app/base.py", line 67, in wsgi
    self.callable = self.load()
  File "/home/ubuntu/virtualenv/vulndemo/lib/python3.10/site-packages/gunicorn/app/wsgiapp.py", line 58, in load
    return self.load_wsgiapp()
  File "/home/ubuntu/virtualenv/vulndemo/lib/python3.10/site-packages/gunicorn/app/wsgiapp.py", line 48, in load_wsgiapp
    return util.import_app(self.app_uri)
  File "/home/ubuntu/virtualenv/vulndemo/lib/python3.10/site-packages/gunicorn/util.py", line 359, in import_app
    mod = importlib.import_module(module)
  File "/usr/lib/python3.10/importlib/__init__.py", line 126, in import_module
    return _bootstrap._gcd_import(name[level:], package, level)
  File "<frozen importlib._bootstrap>", line 1050, in _gcd_import
  File "<frozen importlib._bootstrap>", line 1027, in _find_and_load
  File "<frozen importlib._bootstrap>", line 1006, in _find_and_load_unlocked
  File "<frozen importlib._bootstrap>", line 688, in _load_unlocked
  File "<frozen importlib._bootstrap_external>", line 883, in exec_module
  File "<frozen importlib._bootstrap>", line 241, in _call_with_frames_removed
  File "/home/ubuntu/work/app.py", line 7, in <module>
    from flask_cors import CORS, cross_origin
ModuleNotFoundError: No module named 'flask_cors'
[2022-12-02 15:42:06 +0800] [815768] [INFO] Worker exiting (pid: 815768)
Traceback (most recent call last):
  File "src/gevent/greenlet.py", line 908, in gevent._gevent_cgreenlet.Greenlet.run
  File "/home/ubuntu/virtualenv/vulndemo/lib/python3.10/site-packages/gunicorn/arbiter.py", line 242, in handle_chld
    self.reap_workers()
  File "/home/ubuntu/virtualenv/vulndemo/lib/python3.10/site-packages/gunicorn/arbiter.py", line 525, in reap_workers
    raise HaltServer(reason, self.WORKER_BOOT_ERROR)
gunicorn.errors.HaltServer: <HaltServer 'Worker failed to boot.' 3>
2022-12-02T07:42:06Z <Greenlet at 0x7f2343a9a700: <bound method Arbiter.handle_chld of <gunicorn.arbiter.Arbiter object at 0x7f2343a79f90>>(17, None)> failed with HaltServer

[2022-12-02 15:42:06 +0800] [815769] [ERROR] Exception in worker process
Traceback (most recent call last):
  File "/home/ubuntu/virtualenv/vulndemo/lib/python3.10/site-packages/gunicorn/arbiter.py", line 589, in spawn_worker
    worker.init_process()
  File "/home/ubuntu/virtualenv/vulndemo/lib/python3.10/site-packages/gunicorn/workers/ggevent.py", line 146, in init_process
    super().init_process()
  File "/home/ubuntu/virtualenv/vulndemo/lib/python3.10/site-packages/gunicorn/workers/base.py", line 134, in init_process
    self.load_wsgi()
  File "/home/ubuntu/virtualenv/vulndemo/lib/python3.10/site-packages/gunicorn/workers/base.py", line 146, in load_wsgi
    self.wsgi = self.app.wsgi()
  File "/home/ubuntu/virtualenv/vulndemo/lib/python3.10/site-packages/gunicorn/app/base.py", line 67, in wsgi
    self.callable = self.load()
  File "/home/ubuntu/virtualenv/vulndemo/lib/python3.10/site-packages/gunicorn/app/wsgiapp.py", line 58, in load
    return self.load_wsgiapp()
  File "/home/ubuntu/virtualenv/vulndemo/lib/python3.10/site-packages/gunicorn/app/wsgiapp.py", line 48, in load_wsgiapp
    return util.import_app(self.app_uri)
  File "/home/ubuntu/virtualenv/vulndemo/lib/python3.10/site-packages/gunicorn/util.py", line 359, in import_app
    mod = importlib.import_module(module)
  File "/usr/lib/python3.10/importlib/__init__.py", line 126, in import_module
    return _bootstrap._gcd_import(name[level:], package, level)
  File "<frozen importlib._bootstrap>", line 1050, in _gcd_import
  File "<frozen importlib._bootstrap>", line 1027, in _find_and_load
  File "<frozen importlib._bootstrap>", line 1006, in _find_and_load_unlocked
  File "<frozen importlib._bootstrap>", line 688, in _load_unlocked
  File "<frozen importlib._bootstrap_external>", line 883, in exec_module
  File "<frozen importlib._bootstrap>", line 241, in _call_with_frames_removed
  File "/home/ubuntu/work/app.py", line 7, in <module>
    from flask_cors import CORS, cross_origin
ModuleNotFoundError: No module named 'flask_cors'
[2022-12-02 15:42:06 +0800] [815769] [INFO] Worker exiting (pid: 815769)
Traceback (most recent call last):
  File "src/gevent/greenlet.py", line 908, in gevent._gevent_cgreenlet.Greenlet.run
  File "/home/ubuntu/virtualenv/vulndemo/lib/python3.10/site-packages/gunicorn/arbiter.py", line 242, in handle_chld
    self.reap_workers()
  File "/home/ubuntu/virtualenv/vulndemo/lib/python3.10/site-packages/gunicorn/arbiter.py", line 525, in reap_workers
    raise HaltServer(reason, self.WORKER_BOOT_ERROR)
gunicorn.errors.HaltServer: <HaltServer 'Worker failed to boot.' 3>
